<robot name = "robot">
    <link name="0">
        <inertial>
            <origin xyz="0 0 0" rpy="0 0 0"/>
            <mass value="1" />
            <inertia ixx="100" ixy="0" ixz="0" iyy="100" iyz="0" izz="100" />
        </inertial>
        <visual>
            <origin xyz="0 0 0" rpy="0 0 0"/>
            <geometry>
                <box size="0.1992113791858286 0.5554741975973816 0.10838695362366867" />
            </geometry>
            <material name="Cyan">
                <color rgba="0 1 0 1"/>
            </material>
        </visual>
        <collision>
            <origin xyz="0 0 0" rpy="0 0 0"/>
            <geometry>
                <box size="0.1992113791858286 0.5554741975973816 0.10838695362366867" />
            </geometry>
        </collision>
    </link>
    <joint name="Joint0_1" type="revolute">
       <parent link="0"/>
       <child  link="1"/>
       <origin rpy="0 0 0" xyz="0.0 0.0 0.05419347681183433" />
     <axis xyz="0 1 0"/>
       <limit effort="0.0" lower="-3.14159" upper="3.14159" velocity="0.0"/>
    </joint>
    <link name="1">
        <inertial>
            <origin xyz="0.0 0.0 0.07180027909066064" rpy="0 0 0"/>
            <mass value="1" />
            <inertia ixx="100" ixy="0" ixz="0" iyy="100" iyz="0" izz="100" />
        </inertial>
        <visual>
            <origin xyz="0.0 0.0 0.07180027909066064" rpy="0 0 0"/>
            <geometry>
                <box size="0.3870232877241976 0.6133510981557664 0.14360055818132128" />
            </geometry>
            <material name="Blue">
                <color rgba="0 1 0 1"/>
            </material>
        </visual>
        <collision>
            <origin xyz="0.0 0.0 0.07180027909066064" rpy="0 0 0"/>
            <geometry>
                <box size="0.3870232877241976 0.6133510981557664 0.14360055818132128" />
            </geometry>
        </collision>
    </link>
    <joint name="Joint1_2" type="revolute">
       <parent link="1"/>
       <child  link="2"/>
       <origin rpy="0 0 0" xyz="0.0 -0.3066755490778832 0.07180027909066064" />
     <axis xyz="0 1 0"/>
       <limit effort="0.0" lower="-3.14159" upper="3.14159" velocity="0.0"/>
    </joint>
    <link name="2">
        <inertial>
            <origin xyz="-0.0 8.890737424954753e-10 0.0" rpy="0 0 0"/>
            <mass value="1" />
            <inertia ixx="100" ixy="0" ixz="0" iyy="100" iyz="0" izz="100" />
        </inertial>
        <visual>
            <origin xyz="-0.0 8.890737424954753e-10 0.0" rpy="0 0 0"/>
            <geometry>
                <box size="-3.42750582787599e-10 -1.7781474849909506e-09 -2.1600266735973077e-11" />
            </geometry>
            <material name="Blue">
                <color rgba="0 1 0 1"/>
            </material>
        </visual>
        <collision>
            <origin xyz="-0.0 8.890737424954753e-10 0.0" rpy="0 0 0"/>
            <geometry>
                <box size="-3.42750582787599e-10 -1.7781474849909506e-09 -2.1600266735973077e-11" />
            </geometry>
        </collision>
    </link>
    <joint name="Joint1_3" type="revolute">
       <parent link="1"/>
       <child  link="3"/>
       <origin rpy="0 0 0" xyz="0.0 0.0 0.14360055818132128" />
     <axis xyz="0 1 0"/>
       <limit effort="0.0" lower="-3.14159" upper="3.14159" velocity="0.0"/>
    </joint>
    <link name="3">
        <inertial>
            <origin xyz="0.0 0.0 0.24505501128286644" rpy="0 0 0"/>
            <mass value="1" />
            <inertia ixx="100" ixy="0" ixz="0" iyy="100" iyz="0" izz="100" />
        </inertial>
        <visual>
            <origin xyz="0.0 0.0 0.24505501128286644" rpy="0 0 0"/>
            <geometry>
                <box size="0.47895825370310857 0.5085744291479096 0.4901100225657329" />
            </geometry>
            <material name="Blue">
                <color rgba="0 1 0 1"/>
            </material>
        </visual>
        <collision>
            <origin xyz="0.0 0.0 0.24505501128286644" rpy="0 0 0"/>
            <geometry>
                <box size="0.47895825370310857 0.5085744291479096 0.4901100225657329" />
            </geometry>
        </collision>
    </link>
    <joint name="Joint1_9" type="revolute">
       <parent link="1"/>
       <child  link="9"/>
       <origin rpy="0 0 0" xyz="-0.1935116438620988 0.0 0.07180027909066064" />
     <axis xyz="1 0 0"/>
       <limit effort="0.0" lower="-3.14159" upper="3.14159" velocity="0.0"/>
    </joint>
    <link name="9">
        <inertial>
            <origin xyz="-0.18895242050686906 0.0 0.0" rpy="0 0 0"/>
            <mass value="1" />
            <inertia ixx="100" ixy="0" ixz="0" iyy="100" iyz="0" izz="100" />
        </inertial>
        <visual>
            <origin xyz="-0.18895242050686906 0.0 0.0" rpy="0 0 0"/>
            <geometry>
                <box size="0.3779048410137381 0.07080430283768756 0.11276850558857224" />
            </geometry>
            <material name="Blue">
                <color rgba="0 1 0 1"/>
            </material>
        </visual>
        <collision>
            <origin xyz="-0.18895242050686906 0.0 0.0" rpy="0 0 0"/>
            <geometry>
                <box size="0.3779048410137381 0.07080430283768756 0.11276850558857224" />
            </geometry>
        </collision>
    </link>
    <joint name="Joint2_6" type="revolute">
       <parent link="2"/>
       <child  link="6"/>
       <origin rpy="0 0 0" xyz="1.713752913937995e-10 8.890737424954753e-10 -0.0" />
     <axis xyz="1 0 0"/>
       <limit effort="0.0" lower="-3.14159" upper="3.14159" velocity="0.0"/>
    </joint>
    <link name="6">
        <inertial>
            <origin xyz="-0.08755758206863053 0.0 0.0" rpy="0 0 0"/>
            <mass value="1" />
            <inertia ixx="100" ixy="0" ixz="0" iyy="100" iyz="0" izz="100" />
        </inertial>
        <visual>
            <origin xyz="-0.08755758206863053 0.0 0.0" rpy="0 0 0"/>
            <geometry>
                <box size="0.17511516413726105 0.18084467294954 0.1270757201892317" />
            </geometry>
            <material name="Green">
                <color rgba="0 1 1 1"/>
            </material>
        </visual>
        <collision>
            <origin xyz="-0.08755758206863053 0.0 0.0" rpy="0 0 0"/>
            <geometry>
                <box size="0.17511516413726105 0.18084467294954 0.1270757201892317" />
            </geometry>
        </collision>
    </link>
    <joint name="Joint3_4" type="revolute">
       <parent link="3"/>
       <child  link="4"/>
       <origin rpy="0 0 0" xyz="0.0 0.0 0.4901100225657329" />
     <axis xyz="0 1 0"/>
       <limit effort="0.0" lower="-3.14159" upper="3.14159" velocity="0.0"/>
    </joint>
    <link name="4">
        <inertial>
            <origin xyz="-0.0 0.0 0.0003217617953387116" rpy="0 0 0"/>
            <mass value="1" />
            <inertia ixx="100" ixy="0" ixz="0" iyy="100" iyz="0" izz="100" />
        </inertial>
        <visual>
            <origin xyz="-0.0 0.0 0.0003217617953387116" rpy="0 0 0"/>
            <geometry>
                <box size="-0.00031889265712009335 1.643845692934919e-05 0.0006435235906774232" />
            </geometry>
            <material name="Blue">
                <color rgba="0 1 0 1"/>
            </material>
        </visual>
        <collision>
            <origin xyz="-0.0 0.0 0.0003217617953387116" rpy="0 0 0"/>
            <geometry>
                <box size="-0.00031889265712009335 1.643845692934919e-05 0.0006435235906774232" />
            </geometry>
        </collision>
    </link>
    <joint name="Joint3_7" type="revolute">
       <parent link="3"/>
       <child  link="7"/>
       <origin rpy="0 0 0" xyz="0.23947912685155429 0.0 0.24505501128286644" />
     <axis xyz="1 0 0"/>
       <limit effort="0.0" lower="-3.14159" upper="3.14159" velocity="0.0"/>
    </joint>
    <link name="7">
        <inertial>
            <origin xyz="0.004642497272099668 -0.0 0.0" rpy="0 0 0"/>
            <mass value="1" />
            <inertia ixx="100" ixy="0" ixz="0" iyy="100" iyz="0" izz="100" />
        </inertial>
        <visual>
            <origin xyz="0.004642497272099668 -0.0 0.0" rpy="0 0 0"/>
            <geometry>
                <box size="0.009284994544199336 -0.0064275949998686965 0.023630066571941825" />
            </geometry>
            <material name="Blue">
                <color rgba="0 1 0 1"/>
            </material>
        </visual>
        <collision>
            <origin xyz="0.004642497272099668 -0.0 0.0" rpy="0 0 0"/>
            <geometry>
                <box size="0.009284994544199336 -0.0064275949998686965 0.023630066571941825" />
            </geometry>
        </collision>
    </link>
    <joint name="Joint6_8" type="revolute">
       <parent link="6"/>
       <child  link="8"/>
       <origin rpy="0 0 0" xyz="-0.08755758206863053 -0.09042233647477 0.0" />
     <axis xyz="0 1 0"/>
       <limit effort="0.0" lower="-3.14159" upper="3.14159" velocity="0.0"/>
    </joint>
    <link name="8">
        <inertial>
            <origin xyz="0.0 -1.9409470582542697e-05 0.0" rpy="0 0 0"/>
            <mass value="1" />
            <inertia ixx="100" ixy="0" ixz="0" iyy="100" iyz="0" izz="100" />
        </inertial>
        <visual>
            <origin xyz="0.0 -1.9409470582542697e-05 0.0" rpy="0 0 0"/>
            <geometry>
                <box size="0.0001316298225024573 3.8818941165085394e-05 -0.00031248912171296235" />
            </geometry>
            <material name="Blue">
                <color rgba="0 1 0 1"/>
            </material>
        </visual>
        <collision>
            <origin xyz="0.0 -1.9409470582542697e-05 0.0" rpy="0 0 0"/>
            <geometry>
                <box size="0.0001316298225024573 3.8818941165085394e-05 -0.00031248912171296235" />
            </geometry>
        </collision>
    </link>
    <joint name="Joint4_5" type="revolute">
       <parent link="4"/>
       <child  link="5"/>
       <origin rpy="0 0 0" xyz="-0.0 -8.219228464674595e-06 0.0003217617953387116" />
     <axis xyz="0 1 0"/>
       <limit effort="0.0" lower="-3.14159" upper="3.14159" velocity="0.0"/>
    </joint>
    <link name="5">
        <inertial>
            <origin xyz="0.0 0.0013735198394636751 0.0" rpy="0 0 0"/>
            <mass value="1" />
            <inertia ixx="100" ixy="0" ixz="0" iyy="100" iyz="0" izz="100" />
        </inertial>
        <visual>
            <origin xyz="0.0 0.0013735198394636751 0.0" rpy="0 0 0"/>
            <geometry>
                <box size="0.0003054564398662563 -0.0027470396789273503 0.007594728385422503" />
            </geometry>
            <material name="Blue">
                <color rgba="0 1 0 1"/>
            </material>
        </visual>
        <collision>
            <origin xyz="0.0 0.0013735198394636751 0.0" rpy="0 0 0"/>
            <geometry>
                <box size="0.0003054564398662563 -0.0027470396789273503 0.007594728385422503" />
            </geometry>
        </collision>
    </link>
    <joint name="Joint7_12" type="revolute">
       <parent link="7"/>
       <child  link="12"/>
       <origin rpy="0 0 0" xyz="0.004642497272099668 -0.0 -0.011815033285970913" />
     <axis xyz="0 1 0"/>
       <limit effort="0.0" lower="-3.14159" upper="3.14159" velocity="0.0"/>
    </joint>
    <link name="12">
        <inertial>
            <origin xyz="-0.0 -0.0 -9.403562198633713e-05" rpy="0 0 0"/>
            <mass value="1" />
            <inertia ixx="100" ixy="0" ixz="0" iyy="100" iyz="0" izz="100" />
        </inertial>
        <visual>
            <origin xyz="-0.0 -0.0 -9.403562198633713e-05" rpy="0 0 0"/>
            <geometry>
                <box size="-0.00014876411693010345 -8.367166858389986e-06 0.00018807124397267425" />
            </geometry>
            <material name="Blue">
                <color rgba="0 1 0 1"/>
            </material>
        </visual>
        <collision>
            <origin xyz="-0.0 -0.0 -9.403562198633713e-05" rpy="0 0 0"/>
            <geometry>
                <box size="-0.00014876411693010345 -8.367166858389986e-06 0.00018807124397267425" />
            </geometry>
        </collision>
    </link>
    <joint name="Joint5_10" type="revolute">
       <parent link="5"/>
       <child  link="10"/>
       <origin rpy="0 0 0" xyz="0.0 0.0027470396789273503 0.0" />
     <axis xyz="0 1 0"/>
       <limit effort="0.0" lower="-3.14159" upper="3.14159" velocity="0.0"/>
    </joint>
    <link name="10">
        <inertial>
            <origin xyz="0.0 0.002063190377927484 0.0" rpy="0 0 0"/>
            <mass value="1" />
            <inertia ixx="100" ixy="0" ixz="0" iyy="100" iyz="0" izz="100" />
        </inertial>
        <visual>
            <origin xyz="0.0 0.002063190377927484 0.0" rpy="0 0 0"/>
            <geometry>
                <box size="0.002872710803613396 -0.004126380755854968 0.01260331136148482" />
            </geometry>
            <material name="Blue">
                <color rgba="0 1 0 1"/>
            </material>
        </visual>
        <collision>
            <origin xyz="0.0 0.002063190377927484 0.0" rpy="0 0 0"/>
            <geometry>
                <box size="0.002872710803613396 -0.004126380755854968 0.01260331136148482" />
            </geometry>
        </collision>
    </link>
    <joint name="Joint5_11" type="revolute">
       <parent link="5"/>
       <child  link="11"/>
       <origin rpy="0 0 0" xyz="-0.00015272821993312814 0.0013735198394636751 0.0" />
     <axis xyz="1 0 0"/>
       <limit effort="0.0" lower="-3.14159" upper="3.14159" velocity="0.0"/>
    </joint>
    <link name="11">
        <inertial>
            <origin xyz="-0.12785006265331816 0.0 0.0" rpy="0 0 0"/>
            <mass value="1" />
            <inertia ixx="100" ixy="0" ixz="0" iyy="100" iyz="0" izz="100" />
        </inertial>
        <visual>
            <origin xyz="-0.12785006265331816 0.0 0.0" rpy="0 0 0"/>
            <geometry>
                <box size="0.25570012530663633 0.591293064162213 0.48033222651191015" />
            </geometry>
            <material name="Blue">
                <color rgba="0 1 0 1"/>
            </material>
        </visual>
        <collision>
            <origin xyz="-0.12785006265331816 0.0 0.0" rpy="0 0 0"/>
            <geometry>
                <box size="0.25570012530663633 0.591293064162213 0.48033222651191015" />
            </geometry>
        </collision>
    </link>
    <joint name="Joint11_13" type="revolute">
       <parent link="11"/>
       <child  link="13"/>
       <origin rpy="0 0 0" xyz="-0.25570012530663633 0.0 0.0" />
     <axis xyz="1 0 0"/>
       <limit effort="0.0" lower="-3.14159" upper="3.14159" velocity="0.0"/>
    </joint>
    <link name="13">
        <inertial>
            <origin xyz="-0.17229177598949252 0.0 0.0" rpy="0 0 0"/>
            <mass value="1" />
            <inertia ixx="100" ixy="0" ixz="0" iyy="100" iyz="0" izz="100" />
        </inertial>
        <visual>
            <origin xyz="-0.17229177598949252 0.0 0.0" rpy="0 0 0"/>
            <geometry>
                <box size="0.34458355197898505 0.5669814927184098 0.586131011479454" />
            </geometry>
            <material name="Blue">
                <color rgba="0 1 0 1"/>
            </material>
        </visual>
        <collision>
            <origin xyz="-0.17229177598949252 0.0 0.0" rpy="0 0 0"/>
            <geometry>
                <box size="0.34458355197898505 0.5669814927184098 0.586131011479454" />
            </geometry>
        </collision>
    </link>
    <joint name="Joint13_14" type="revolute">
       <parent link="13"/>
       <child  link="14"/>
       <origin rpy="0 0 0" xyz="-0.17229177598949252 0.0 0.293065505739727" />
     <axis xyz="0 1 0"/>
       <limit effort="0.0" lower="-3.14159" upper="3.14159" velocity="0.0"/>
    </joint>
    <link name="14">
        <inertial>
            <origin xyz="-0.0 -0.0 -5.079041787716348e-06" rpy="0 0 0"/>
            <mass value="1" />
            <inertia ixx="100" ixy="0" ixz="0" iyy="100" iyz="0" izz="100" />
        </inertial>
        <visual>
            <origin xyz="-0.0 -0.0 -5.079041787716348e-06" rpy="0 0 0"/>
            <geometry>
                <box size="-7.945125794301383e-07 -3.2964213257828195e-08 -1.0158083575432695e-05" />
            </geometry>
            <material name="Blue">
                <color rgba="0 1 0 1"/>
            </material>
        </visual>
        <collision>
            <origin xyz="-0.0 -0.0 -5.079041787716348e-06" rpy="0 0 0"/>
            <geometry>
                <box size="-7.945125794301383e-07 -3.2964213257828195e-08 -1.0158083575432695e-05" />
            </geometry>
        </collision>
    </link>
</robot>