<robot name = "robot">
    <link name="0">
        <inertial>
            <origin xyz="0 0 0" rpy="0 0 0"/>
            <mass value="1" />
            <inertia ixx="100" ixy="0" ixz="0" iyy="100" iyz="0" izz="100" />
        </inertial>
        <visual>
            <origin xyz="0 0 0" rpy="0 0 0"/>
            <geometry>
                <box size="0.12189962053842948 0.29763494556640857 0.2016288538424607" />
            </geometry>
            <material name="Cyan">
                <color rgba="0 1 0 1"/>
            </material>
        </visual>
        <collision>
            <origin xyz="0 0 0" rpy="0 0 0"/>
            <geometry>
                <box size="0.12189962053842948 0.29763494556640857 0.2016288538424607" />
            </geometry>
        </collision>
    </link>
    <joint name="Joint0_1" type="revolute">
       <parent link="0"/>
       <child  link="1"/>
       <origin rpy="0 0 0" xyz="0.0 0.0 0.10081442692123035" />
     <axis xyz="1 1 0"/>
       <limit effort="0.0" lower="-3.14159" upper="3.14159" velocity="0.0"/>
    </joint>
    <link name="1">
        <inertial>
            <origin xyz="0.0 0.0 0.23151043695494197" rpy="0 0 0"/>
            <mass value="1" />
            <inertia ixx="100" ixy="0" ixz="0" iyy="100" iyz="0" izz="100" />
        </inertial>
        <visual>
            <origin xyz="0.0 0.0 0.23151043695494197" rpy="0 0 0"/>
            <geometry>
                <box size="0.1120309515809531 0.4235111302319279 0.46302087390988395" />
            </geometry>
            <material name="Blue">
                <color rgba="0 1 0 1"/>
            </material>
        </visual>
        <collision>
            <origin xyz="0.0 0.0 0.23151043695494197" rpy="0 0 0"/>
            <geometry>
                <box size="0.1120309515809531 0.4235111302319279 0.46302087390988395" />
            </geometry>
        </collision>
    </link>
    <joint name="Joint1_2" type="revolute">
       <parent link="1"/>
       <child  link="2"/>
       <origin rpy="0 0 0" xyz="0.0 0.21175556511596394 0.23151043695494197" />
     <axis xyz="1 0 1"/>
       <limit effort="0.0" lower="-3.14159" upper="3.14159" velocity="0.0"/>
    </joint>
    <link name="2">
        <inertial>
            <origin xyz="0.0 0.11758250081323114 0.0" rpy="0 0 0"/>
            <mass value="1" />
            <inertia ixx="100" ixy="0" ixz="0" iyy="100" iyz="0" izz="100" />
        </inertial>
        <visual>
            <origin xyz="0.0 0.11758250081323114 0.0" rpy="0 0 0"/>
            <geometry>
                <box size="0.064326800594644 0.23516500162646228 0.48294416375004007" />
            </geometry>
            <material name="Blue">
                <color rgba="0 1 0 1"/>
            </material>
        </visual>
        <collision>
            <origin xyz="0.0 0.11758250081323114 0.0" rpy="0 0 0"/>
            <geometry>
                <box size="0.064326800594644 0.23516500162646228 0.48294416375004007" />
            </geometry>
        </collision>
    </link>
    <joint name="Joint2_3" type="revolute">
       <parent link="2"/>
       <child  link="3"/>
       <origin rpy="0 0 0" xyz="0.0 0.23516500162646228 0.0" />
     <axis xyz="1 0 1"/>
       <limit effort="0.0" lower="-3.14159" upper="3.14159" velocity="0.0"/>
    </joint>
    <link name="3">
        <inertial>
            <origin xyz="0.0 0.22032965576319913 0.0" rpy="0 0 0"/>
            <mass value="1" />
            <inertia ixx="100" ixy="0" ixz="0" iyy="100" iyz="0" izz="100" />
        </inertial>
        <visual>
            <origin xyz="0.0 0.22032965576319913 0.0" rpy="0 0 0"/>
            <geometry>
                <box size="0.4132612069875101 0.44065931152639826 0.17922731952808096" />
            </geometry>
            <material name="Blue">
                <color rgba="0 1 0 1"/>
            </material>
        </visual>
        <collision>
            <origin xyz="0.0 0.22032965576319913 0.0" rpy="0 0 0"/>
            <geometry>
                <box size="0.4132612069875101 0.44065931152639826 0.17922731952808096" />
            </geometry>
        </collision>
    </link>
</robot>