<robot name = "robot">
    <link name="Back0">
        <inertial>
            <origin xyz="0 0 0" rpy="0 0 0"/>
            <mass value="1" />
            <inertia ixx="100" ixy="0" ixz="0" iyy="100" iyz="0" izz="100" />
        </inertial>
        <visual>
            <origin xyz="0 0 0" rpy="0 0 0"/>
            <geometry>
                <box size="0.35310646610102026 0.5694636006708913 0.10261864644962179" />
            </geometry>
            <material name="Green">
                <color rgba="0 1 1 1"/>
            </material>
        </visual>
        <collision>
            <origin xyz="0 0 0" rpy="0 0 0"/>
            <geometry>
                <box size="0.35310646610102026 0.5694636006708913 0.10261864644962179" />
            </geometry>
        </collision>
    </link>
    <joint name="Back0_Back1" type="revolute">
       <parent link="Back0"/>
       <child  link="Back1"/>
       <origin rpy="0 0 0" xyz="0 -0.28473180033544565 0.0" />
     <axis xyz="0 0 1"/>
       <limit effort="0.0" lower="-3.14159" upper="3.14159" velocity="0.0"/>
    </joint>
    <link name="Back1">
        <inertial>
            <origin xyz="0 -0.3148409018418793 -0.15" rpy="0 0 0"/>
            <mass value="1" />
            <inertia ixx="100" ixy="0" ixz="0" iyy="100" iyz="0" izz="100" />
        </inertial>
        <visual>
            <origin xyz="0 -0.3148409018418793 -0.15" rpy="0 0 0"/>
            <geometry>
                <box size="0.3076893861794662 0.6296818036837586 0.08253798782140517" />
            </geometry>
            <material name="Green">
                <color rgba="0 1 1 1"/>
            </material>
        </visual>
        <collision>
            <origin xyz="0 -0.3148409018418793 -0.15" rpy="0 0 0"/>
            <geometry>
                <box size="0.3076893861794662 0.6296818036837586 0.08253798782140517" />
            </geometry>
        </collision>
    </link>
    <joint name="Back1_Back2" type="revolute">
       <parent link="Back1"/>
       <child  link="Back2"/>
       <origin rpy="0 0 0" xyz="0 -0.6296818036837586 0.0" />
     <axis xyz="0 0 1"/>
       <limit effort="0.0" lower="-3.14159" upper="3.14159" velocity="0.0"/>
    </joint>
    <link name="Back2">
        <inertial>
            <origin xyz="0 -0.29437969087587135 -0.15" rpy="0 0 0"/>
            <mass value="1" />
            <inertia ixx="100" ixy="0" ixz="0" iyy="100" iyz="0" izz="100" />
        </inertial>
        <visual>
            <origin xyz="0 -0.29437969087587135 -0.15" rpy="0 0 0"/>
            <geometry>
                <box size="0.3066392257073435 0.5887593817517427 0.17148042592285168" />
            </geometry>
            <material name="Green">
                <color rgba="0 1 1 1"/>
            </material>
        </visual>
        <collision>
            <origin xyz="0 -0.29437969087587135 -0.15" rpy="0 0 0"/>
            <geometry>
                <box size="0.3066392257073435 0.5887593817517427 0.17148042592285168" />
            </geometry>
        </collision>
    </link>
    <joint name="Back2_Back3" type="revolute">
       <parent link="Back2"/>
       <child  link="Back3"/>
       <origin rpy="0 0 0" xyz="0 -0.5887593817517427 0.0" />
     <axis xyz="1 0 0"/>
       <limit effort="0.0" lower="-3.14159" upper="3.14159" velocity="0.0"/>
    </joint>
    <link name="Back3">
        <inertial>
            <origin xyz="0 -0.20928406972527058 -0.15" rpy="0 0 0"/>
            <mass value="1" />
            <inertia ixx="100" ixy="0" ixz="0" iyy="100" iyz="0" izz="100" />
        </inertial>
        <visual>
            <origin xyz="0 -0.20928406972527058 -0.15" rpy="0 0 0"/>
            <geometry>
                <box size="0.25551479857521187 0.41856813945054117 0.5955588269361973" />
            </geometry>
            <material name="Green">
                <color rgba="0 1 1 1"/>
            </material>
        </visual>
        <collision>
            <origin xyz="0 -0.20928406972527058 -0.15" rpy="0 0 0"/>
            <geometry>
                <box size="0.25551479857521187 0.41856813945054117 0.5955588269361973" />
            </geometry>
        </collision>
    </link>
    <joint name="Back3_Back4" type="revolute">
       <parent link="Back3"/>
       <child  link="Back4"/>
       <origin rpy="0 0 0" xyz="0 -0.41856813945054117 0.0" />
     <axis xyz="0 0 1"/>
       <limit effort="0.0" lower="-3.14159" upper="3.14159" velocity="0.0"/>
    </joint>
    <link name="Back4">
        <inertial>
            <origin xyz="0 -0.2102551625660702 -0.15" rpy="0 0 0"/>
            <mass value="1" />
            <inertia ixx="100" ixy="0" ixz="0" iyy="100" iyz="0" izz="100" />
        </inertial>
        <visual>
            <origin xyz="0 -0.2102551625660702 -0.15" rpy="0 0 0"/>
            <geometry>
                <box size="0.43196865901504966 0.4205103251321404 0.16331382283876417" />
            </geometry>
            <material name="Green">
                <color rgba="0 1 1 1"/>
            </material>
        </visual>
        <collision>
            <origin xyz="0 -0.2102551625660702 -0.15" rpy="0 0 0"/>
            <geometry>
                <box size="0.43196865901504966 0.4205103251321404 0.16331382283876417" />
            </geometry>
        </collision>
    </link>
    <joint name="Back4_Back5" type="revolute">
       <parent link="Back4"/>
       <child  link="Back5"/>
       <origin rpy="0 0 0" xyz="0 -0.4205103251321404 0.0" />
     <axis xyz="0 0 1"/>
       <limit effort="0.0" lower="-3.14159" upper="3.14159" velocity="0.0"/>
    </joint>
    <link name="Back5">
        <inertial>
            <origin xyz="0 -0.2606781441914898 -0.15" rpy="0 0 0"/>
            <mass value="1" />
            <inertia ixx="100" ixy="0" ixz="0" iyy="100" iyz="0" izz="100" />
        </inertial>
        <visual>
            <origin xyz="0 -0.2606781441914898 -0.15" rpy="0 0 0"/>
            <geometry>
                <box size="0.08075396385941108 0.5213562883829796 0.5374836080381042" />
            </geometry>
            <material name="Blue">
                <color rgba="0 1 0 1"/>
            </material>
        </visual>
        <collision>
            <origin xyz="0 -0.2606781441914898 -0.15" rpy="0 0 0"/>
            <geometry>
                <box size="0.08075396385941108 0.5213562883829796 0.5374836080381042" />
            </geometry>
        </collision>
    </link>
    <joint name="Back5_Back6" type="revolute">
       <parent link="Back5"/>
       <child  link="Back6"/>
       <origin rpy="0 0 0" xyz="0 -0.5213562883829796 0.0" />
     <axis xyz="1 0 0"/>
       <limit effort="0.0" lower="-3.14159" upper="3.14159" velocity="0.0"/>
    </joint>
    <link name="Back6">
        <inertial>
            <origin xyz="0 -0.2843533629945785 -0.15" rpy="0 0 0"/>
            <mass value="1" />
            <inertia ixx="100" ixy="0" ixz="0" iyy="100" iyz="0" izz="100" />
        </inertial>
        <visual>
            <origin xyz="0 -0.2843533629945785 -0.15" rpy="0 0 0"/>
            <geometry>
                <box size="0.3699129134347183 0.568706725989157 0.16333216001166606" />
            </geometry>
            <material name="Green">
                <color rgba="0 1 1 1"/>
            </material>
        </visual>
        <collision>
            <origin xyz="0 -0.2843533629945785 -0.15" rpy="0 0 0"/>
            <geometry>
                <box size="0.3699129134347183 0.568706725989157 0.16333216001166606" />
            </geometry>
        </collision>
    </link>
    <joint name="Back6_Back7" type="revolute">
       <parent link="Back6"/>
       <child  link="Back7"/>
       <origin rpy="0 0 0" xyz="0 -0.568706725989157 0.0" />
     <axis xyz="0 0 1"/>
       <limit effort="0.0" lower="-3.14159" upper="3.14159" velocity="0.0"/>
    </joint>
    <link name="Back7">
        <inertial>
            <origin xyz="0 -0.1709158387160449 -0.15" rpy="0 0 0"/>
            <mass value="1" />
            <inertia ixx="100" ixy="0" ixz="0" iyy="100" iyz="0" izz="100" />
        </inertial>
        <visual>
            <origin xyz="0 -0.1709158387160449 -0.15" rpy="0 0 0"/>
            <geometry>
                <box size="0.5258489468567287 0.3418316774320898 0.5699421200886392" />
            </geometry>
            <material name="Green">
                <color rgba="0 1 1 1"/>
            </material>
        </visual>
        <collision>
            <origin xyz="0 -0.1709158387160449 -0.15" rpy="0 0 0"/>
            <geometry>
                <box size="0.5258489468567287 0.3418316774320898 0.5699421200886392" />
            </geometry>
        </collision>
    </link>
    <joint name="Back7_Back8" type="revolute">
       <parent link="Back7"/>
       <child  link="Back8"/>
       <origin rpy="0 0 0" xyz="0 -0.3418316774320898 0.0" />
     <axis xyz="0 0 1"/>
       <limit effort="0.0" lower="-3.14159" upper="3.14159" velocity="0.0"/>
    </joint>
    <link name="Back8">
        <inertial>
            <origin xyz="0 -0.29449810586561675 -0.15" rpy="0 0 0"/>
            <mass value="1" />
            <inertia ixx="100" ixy="0" ixz="0" iyy="100" iyz="0" izz="100" />
        </inertial>
        <visual>
            <origin xyz="0 -0.29449810586561675 -0.15" rpy="0 0 0"/>
            <geometry>
                <box size="0.30153767416509275 0.5889962117312335 0.15128400426722846" />
            </geometry>
            <material name="Green">
                <color rgba="0 1 1 1"/>
            </material>
        </visual>
        <collision>
            <origin xyz="0 -0.29449810586561675 -0.15" rpy="0 0 0"/>
            <geometry>
                <box size="0.30153767416509275 0.5889962117312335 0.15128400426722846" />
            </geometry>
        </collision>
    </link>
    <joint name="Back8_Back9" type="revolute">
       <parent link="Back8"/>
       <child  link="Back9"/>
       <origin rpy="0 0 0" xyz="0 -0.5889962117312335 0.0" />
     <axis xyz="1 0 0"/>
       <limit effort="0.0" lower="-3.14159" upper="3.14159" velocity="0.0"/>
    </joint>
    <link name="Back9">
        <inertial>
            <origin xyz="0 -0.1558501318000451 -0.15" rpy="0 0 0"/>
            <mass value="1" />
            <inertia ixx="100" ixy="0" ixz="0" iyy="100" iyz="0" izz="100" />
        </inertial>
        <visual>
            <origin xyz="0 -0.1558501318000451 -0.15" rpy="0 0 0"/>
            <geometry>
                <box size="0.22361440540322805 0.3117002636000902 0.2831656783337718" />
            </geometry>
            <material name="Green">
                <color rgba="0 1 1 1"/>
            </material>
        </visual>
        <collision>
            <origin xyz="0 -0.1558501318000451 -0.15" rpy="0 0 0"/>
            <geometry>
                <box size="0.22361440540322805 0.3117002636000902 0.2831656783337718" />
            </geometry>
        </collision>
    </link>
</robot>