<robot name = "robot">
    <link name="0">
        <inertial>
            <origin xyz="0 0 0" rpy="0 0 0"/>
            <mass value="1" />
            <inertia ixx="100" ixy="0" ixz="0" iyy="100" iyz="0" izz="100" />
        </inertial>
        <visual>
            <origin xyz="0 0 0" rpy="0 0 0"/>
            <geometry>
                <box size="0.009651142998268348 0.01768703889607825 -0.0068994451038284655" />
            </geometry>
            <material name="Cyan">
                <color rgba="0 1 0 1"/>
            </material>
        </visual>
        <collision>
            <origin xyz="0 0 0" rpy="0 0 0"/>
            <geometry>
                <box size="0.009651142998268348 0.01768703889607825 -0.0068994451038284655" />
            </geometry>
        </collision>
    </link>
    <joint name="Joint0_1" type="revolute">
       <parent link="0"/>
       <child  link="1"/>
       <origin rpy="0 0 0" xyz="0.0 0.0 -0.0034497225519142328" />
     <axis xyz="0 1 0"/>
       <limit effort="0.0" lower="-3.14159" upper="3.14159" velocity="0.0"/>
    </joint>
    <link name="1">
        <inertial>
            <origin xyz="0.0 -0.0 -1.26212395576148e-09" rpy="0 0 0"/>
            <mass value="1" />
            <inertia ixx="100" ixy="0" ixz="0" iyy="100" iyz="0" izz="100" />
        </inertial>
        <visual>
            <origin xyz="0.0 -0.0 -1.26212395576148e-09" rpy="0 0 0"/>
            <geometry>
                <box size="3.410894328822972e-07 -8.988613319526536e-09 -2.52424791152296e-09" />
            </geometry>
            <material name="Blue">
                <color rgba="0 1 0 1"/>
            </material>
        </visual>
        <collision>
            <origin xyz="0.0 -0.0 -1.26212395576148e-09" rpy="0 0 0"/>
            <geometry>
                <box size="3.410894328822972e-07 -8.988613319526536e-09 -2.52424791152296e-09" />
            </geometry>
        </collision>
    </link>
    <joint name="Joint1_2" type="revolute">
       <parent link="1"/>
       <child  link="2"/>
       <origin rpy="0 0 0" xyz="0.0 -0.0 -2.52424791152296e-09" />
     <axis xyz="0 1 0"/>
       <limit effort="0.0" lower="-3.14159" upper="3.14159" velocity="0.0"/>
    </joint>
    <link name="2">
        <inertial>
            <origin xyz="0.0 0.0 3.651269289809739e-11" rpy="0 0 0"/>
            <mass value="1" />
            <inertia ixx="100" ixy="0" ixz="0" iyy="100" iyz="0" izz="100" />
        </inertial>
        <visual>
            <origin xyz="0.0 0.0 3.651269289809739e-11" rpy="0 0 0"/>
            <geometry>
                <box size="6.712950004624467e-11 6.220204695477548e-11 7.302538579619479e-11" />
            </geometry>
            <material name="Blue">
                <color rgba="0 1 0 1"/>
            </material>
        </visual>
        <collision>
            <origin xyz="0.0 0.0 3.651269289809739e-11" rpy="0 0 0"/>
            <geometry>
                <box size="6.712950004624467e-11 6.220204695477548e-11 7.302538579619479e-11" />
            </geometry>
        </collision>
    </link>
    <joint name="Joint2_3" type="revolute">
       <parent link="2"/>
       <child  link="3"/>
       <origin rpy="0 0 0" xyz="-3.3564750023122335e-11 0.0 3.651269289809739e-11" />
     <axis xyz="1 0 0"/>
       <limit effort="0.0" lower="-3.14159" upper="3.14159" velocity="0.0"/>
    </joint>
    <link name="3">
        <inertial>
            <origin xyz="2.0057989412008487e-05 -0.0 0.0" rpy="0 0 0"/>
            <mass value="1" />
            <inertia ixx="100" ixy="0" ixz="0" iyy="100" iyz="0" izz="100" />
        </inertial>
        <visual>
            <origin xyz="2.0057989412008487e-05 -0.0 0.0" rpy="0 0 0"/>
            <geometry>
                <box size="-4.0115978824016975e-05 -9.474829158470648e-05 -0.0001610672411229829" />
            </geometry>
            <material name="Blue">
                <color rgba="0 1 0 1"/>
            </material>
        </visual>
        <collision>
            <origin xyz="2.0057989412008487e-05 -0.0 0.0" rpy="0 0 0"/>
            <geometry>
                <box size="-4.0115978824016975e-05 -9.474829158470648e-05 -0.0001610672411229829" />
            </geometry>
        </collision>
    </link>
    <joint name="Joint2_4" type="revolute">
       <parent link="2"/>
       <child  link="4"/>
       <origin rpy="0 0 0" xyz="0.0 3.110102347738774e-11 3.651269289809739e-11" />
     <axis xyz="0 1 0"/>
       <limit effort="0.0" lower="-3.14159" upper="3.14159" velocity="0.0"/>
    </joint>
    <link name="4">
        <inertial>
            <origin xyz="0.0 0.2000648205462648 0.0" rpy="0 0 0"/>
            <mass value="1" />
            <inertia ixx="100" ixy="0" ixz="0" iyy="100" iyz="0" izz="100" />
        </inertial>
        <visual>
            <origin xyz="0.0 0.2000648205462648 0.0" rpy="0 0 0"/>
            <geometry>
                <box size="0.5081641586951706 0.4001296410925296 0.1496000997619327" />
            </geometry>
            <material name="Blue">
                <color rgba="0 1 0 1"/>
            </material>
        </visual>
        <collision>
            <origin xyz="0.0 0.2000648205462648 0.0" rpy="0 0 0"/>
            <geometry>
                <box size="0.5081641586951706 0.4001296410925296 0.1496000997619327" />
            </geometry>
        </collision>
    </link>
    <joint name="Joint2_5" type="revolute">
       <parent link="2"/>
       <child  link="5"/>
       <origin rpy="0 0 0" xyz="0.0 0.0 7.302538579619479e-11" />
     <axis xyz="0 1 0"/>
       <limit effort="0.0" lower="-3.14159" upper="3.14159" velocity="0.0"/>
    </joint>
    <link name="5">
        <inertial>
            <origin xyz="-0.0 -0.0 -0.003480075091538285" rpy="0 0 0"/>
            <mass value="1" />
            <inertia ixx="100" ixy="0" ixz="0" iyy="100" iyz="0" izz="100" />
        </inertial>
        <visual>
            <origin xyz="-0.0 -0.0 -0.003480075091538285" rpy="0 0 0"/>
            <geometry>
                <box size="-0.007266758139793443 -0.005439349353551155 -0.00696015018307657" />
            </geometry>
            <material name="Blue">
                <color rgba="0 1 0 1"/>
            </material>
        </visual>
        <collision>
            <origin xyz="-0.0 -0.0 -0.003480075091538285" rpy="0 0 0"/>
            <geometry>
                <box size="-0.007266758139793443 -0.005439349353551155 -0.00696015018307657" />
            </geometry>
        </collision>
    </link>
    <joint name="Joint2_6" type="revolute">
       <parent link="2"/>
       <child  link="6"/>
       <origin rpy="0 0 0" xyz="0.0 -3.110102347738774e-11 3.651269289809739e-11" />
     <axis xyz="0 1 0"/>
       <limit effort="0.0" lower="-3.14159" upper="3.14159" velocity="0.0"/>
    </joint>
    <link name="6">
        <inertial>
            <origin xyz="0.0 6.408761829868116e-05 0.0" rpy="0 0 0"/>
            <mass value="1" />
            <inertia ixx="100" ixy="0" ixz="0" iyy="100" iyz="0" izz="100" />
        </inertial>
        <visual>
            <origin xyz="0.0 6.408761829868116e-05 0.0" rpy="0 0 0"/>
            <geometry>
                <box size="0.0010120626662167608 -0.00012817523659736232 3.6558899204281095e-05" />
            </geometry>
            <material name="Green">
                <color rgba="0 1 1 1"/>
            </material>
        </visual>
        <collision>
            <origin xyz="0.0 6.408761829868116e-05 0.0" rpy="0 0 0"/>
            <geometry>
                <box size="0.0010120626662167608 -0.00012817523659736232 3.6558899204281095e-05" />
            </geometry>
        </collision>
    </link>
    <joint name="Joint2_10" type="revolute">
       <parent link="2"/>
       <child  link="10"/>
       <origin rpy="0 0 0" xyz="3.3564750023122335e-11 0.0 3.651269289809739e-11" />
     <axis xyz="1 0 0"/>
       <limit effort="0.0" lower="-3.14159" upper="3.14159" velocity="0.0"/>
    </joint>
    <link name="10">
        <inertial>
            <origin xyz="0.2984829485850109 0.0 0.0" rpy="0 0 0"/>
            <mass value="1" />
            <inertia ixx="100" ixy="0" ixz="0" iyy="100" iyz="0" izz="100" />
        </inertial>
        <visual>
            <origin xyz="0.2984829485850109 0.0 0.0" rpy="0 0 0"/>
            <geometry>
                <box size="0.5969658971700218 0.2901478208880177 0.11564885698037597" />
            </geometry>
            <material name="Blue">
                <color rgba="0 1 0 1"/>
            </material>
        </visual>
        <collision>
            <origin xyz="0.2984829485850109 0.0 0.0" rpy="0 0 0"/>
            <geometry>
                <box size="0.5969658971700218 0.2901478208880177 0.11564885698037597" />
            </geometry>
        </collision>
    </link>
    <joint name="Joint3_13" type="revolute">
       <parent link="3"/>
       <child  link="13"/>
       <origin rpy="0 0 0" xyz="4.0115978824016975e-05 -0.0 -0.0" />
     <axis xyz="1 0 0"/>
       <limit effort="0.0" lower="-3.14159" upper="3.14159" velocity="0.0"/>
    </joint>
    <link name="13">
        <inertial>
            <origin xyz="-4.2667880133088145e-05 0.0 0.0" rpy="0 0 0"/>
            <mass value="1" />
            <inertia ixx="100" ixy="0" ixz="0" iyy="100" iyz="0" izz="100" />
        </inertial>
        <visual>
            <origin xyz="-4.2667880133088145e-05 0.0 0.0" rpy="0 0 0"/>
            <geometry>
                <box size="8.533576026617629e-05 3.491958643723098e-05 -0.00012428477825039092" />
            </geometry>
            <material name="Blue">
                <color rgba="0 1 0 1"/>
            </material>
        </visual>
        <collision>
            <origin xyz="-4.2667880133088145e-05 0.0 0.0" rpy="0 0 0"/>
            <geometry>
                <box size="8.533576026617629e-05 3.491958643723098e-05 -0.00012428477825039092" />
            </geometry>
        </collision>
    </link>
    <joint name="Joint4_9" type="revolute">
       <parent link="4"/>
       <child  link="9"/>
       <origin rpy="0 0 0" xyz="0.0 0.4001296410925296 0.0" />
     <axis xyz="0 1 0"/>
       <limit effort="0.0" lower="-3.14159" upper="3.14159" velocity="0.0"/>
    </joint>
    <link name="9">
        <inertial>
            <origin xyz="0.0 0.1053295313340995 0.0" rpy="0 0 0"/>
            <mass value="1" />
            <inertia ixx="100" ixy="0" ixz="0" iyy="100" iyz="0" izz="100" />
        </inertial>
        <visual>
            <origin xyz="0.0 0.1053295313340995 0.0" rpy="0 0 0"/>
            <geometry>
                <box size="0.5327792909986949 0.210659062668199 0.448916013453712" />
            </geometry>
            <material name="Blue">
                <color rgba="0 1 0 1"/>
            </material>
        </visual>
        <collision>
            <origin xyz="0.0 0.1053295313340995 0.0" rpy="0 0 0"/>
            <geometry>
                <box size="0.5327792909986949 0.210659062668199 0.448916013453712" />
            </geometry>
        </collision>
    </link>
    <joint name="Joint4_14" type="revolute">
       <parent link="4"/>
       <child  link="14"/>
       <origin rpy="0 0 0" xyz="0.2540820793475853 0.2000648205462648 0.0" />
     <axis xyz="1 0 0"/>
       <limit effort="0.0" lower="-3.14159" upper="3.14159" velocity="0.0"/>
    </joint>
    <link name="14">
        <inertial>
            <origin xyz="5.350050291340343e-05 0.0 0.0" rpy="0 0 0"/>
            <mass value="1" />
            <inertia ixx="100" ixy="0" ixz="0" iyy="100" iyz="0" izz="100" />
        </inertial>
        <visual>
            <origin xyz="5.350050291340343e-05 0.0 0.0" rpy="0 0 0"/>
            <geometry>
                <box size="0.00010700100582680687 0.00015411369823428532 -4.975779650113063e-05" />
            </geometry>
            <material name="Blue">
                <color rgba="0 1 0 1"/>
            </material>
        </visual>
        <collision>
            <origin xyz="5.350050291340343e-05 0.0 0.0" rpy="0 0 0"/>
            <geometry>
                <box size="0.00010700100582680687 0.00015411369823428532 -4.975779650113063e-05" />
            </geometry>
        </collision>
    </link>
    <joint name="Joint5_11" type="revolute">
       <parent link="5"/>
       <child  link="11"/>
       <origin rpy="0 0 0" xyz="-0.0036333790698967216 -0.0 -0.003480075091538285" />
     <axis xyz="1 0 0"/>
       <limit effort="0.0" lower="-3.14159" upper="3.14159" velocity="0.0"/>
    </joint>
    <link name="11">
        <inertial>
            <origin xyz="-0.0012061161650661308 -0.0 0.0" rpy="0 0 0"/>
            <mass value="1" />
            <inertia ixx="100" ixy="0" ixz="0" iyy="100" iyz="0" izz="100" />
        </inertial>
        <visual>
            <origin xyz="-0.0012061161650661308 -0.0 0.0" rpy="0 0 0"/>
            <geometry>
                <box size="-0.0024122323301322616 -0.003221738555021586 0.0006711886933738688" />
            </geometry>
            <material name="Blue">
                <color rgba="0 1 0 1"/>
            </material>
        </visual>
        <collision>
            <origin xyz="-0.0012061161650661308 -0.0 0.0" rpy="0 0 0"/>
            <geometry>
                <box size="-0.0024122323301322616 -0.003221738555021586 0.0006711886933738688" />
            </geometry>
        </collision>
    </link>
    <joint name="Joint6_7" type="revolute">
       <parent link="6"/>
       <child  link="7"/>
       <origin rpy="0 0 0" xyz="0.0 0.00012817523659736232 0.0" />
     <axis xyz="0 1 0"/>
       <limit effort="0.0" lower="-3.14159" upper="3.14159" velocity="0.0"/>
    </joint>
    <link name="7">
        <inertial>
            <origin xyz="0.0 2.9500735166235257e-07 0.0" rpy="0 0 0"/>
            <mass value="1" />
            <inertia ixx="100" ixy="0" ixz="0" iyy="100" iyz="0" izz="100" />
        </inertial>
        <visual>
            <origin xyz="0.0 2.9500735166235257e-07 0.0" rpy="0 0 0"/>
            <geometry>
                <box size="1.9994297350442356e-05 -5.900147033247051e-07 -3.107601439442433e-05" />
            </geometry>
            <material name="Blue">
                <color rgba="0 1 0 1"/>
            </material>
        </visual>
        <collision>
            <origin xyz="0.0 2.9500735166235257e-07 0.0" rpy="0 0 0"/>
            <geometry>
                <box size="1.9994297350442356e-05 -5.900147033247051e-07 -3.107601439442433e-05" />
            </geometry>
        </collision>
    </link>
    <joint name="Joint6_8" type="revolute">
       <parent link="6"/>
       <child  link="8"/>
       <origin rpy="0 0 0" xyz="0.0 6.408761829868116e-05 -1.8279449602140547e-05" />
     <axis xyz="0 1 0"/>
       <limit effort="0.0" lower="-3.14159" upper="3.14159" velocity="0.0"/>
    </joint>
    <link name="8">
        <inertial>
            <origin xyz="0.0 0.0 -0.07581586881942405" rpy="0 0 0"/>
            <mass value="1" />
            <inertia ixx="100" ixy="0" ixz="0" iyy="100" iyz="0" izz="100" />
        </inertial>
        <visual>
            <origin xyz="0.0 0.0 -0.07581586881942405" rpy="0 0 0"/>
            <geometry>
                <box size="0.43270995231523757 0.10081132291345249 0.1516317376388481" />
            </geometry>
            <material name="Blue">
                <color rgba="0 1 0 1"/>
            </material>
        </visual>
        <collision>
            <origin xyz="0.0 0.0 -0.07581586881942405" rpy="0 0 0"/>
            <geometry>
                <box size="0.43270995231523757 0.10081132291345249 0.1516317376388481" />
            </geometry>
        </collision>
    </link>
    <joint name="Joint9_12" type="revolute">
       <parent link="9"/>
       <child  link="12"/>
       <origin rpy="0 0 0" xyz="0.0 0.210659062668199 0.0" />
     <axis xyz="0 1 0"/>
       <limit effort="0.0" lower="-3.14159" upper="3.14159" velocity="0.0"/>
    </joint>
    <link name="12">
        <inertial>
            <origin xyz="0.0 0.12718309595262725 0.0" rpy="0 0 0"/>
            <mass value="1" />
            <inertia ixx="100" ixy="0" ixz="0" iyy="100" iyz="0" izz="100" />
        </inertial>
        <visual>
            <origin xyz="0.0 0.12718309595262725 0.0" rpy="0 0 0"/>
            <geometry>
                <box size="0.43569006398952725 0.2543661919052545 0.6128464168775463" />
            </geometry>
            <material name="Blue">
                <color rgba="0 1 0 1"/>
            </material>
        </visual>
        <collision>
            <origin xyz="0.0 0.12718309595262725 0.0" rpy="0 0 0"/>
            <geometry>
                <box size="0.43569006398952725 0.2543661919052545 0.6128464168775463" />
            </geometry>
        </collision>
    </link>
</robot>