<robot name = "robot">
    <link name="0">
        <inertial>
            <origin xyz="0 0 0" rpy="0 0 0"/>
            <mass value="1" />
            <inertia ixx="100" ixy="0" ixz="0" iyy="100" iyz="0" izz="100" />
        </inertial>
        <visual>
            <origin xyz="0 0 0" rpy="0 0 0"/>
            <geometry>
                <box size="6.291451190698164e-07 -2.6827360655250154e-08 2.6702970275997824e-07" />
            </geometry>
            <material name="Cyan">
                <color rgba="0 1 1 1"/>
            </material>
        </visual>
        <collision>
            <origin xyz="0 0 0" rpy="0 0 0"/>
            <geometry>
                <box size="6.291451190698164e-07 -2.6827360655250154e-08 2.6702970275997824e-07" />
            </geometry>
        </collision>
    </link>
    <joint name="Joint0_1" type="revolute">
       <parent link="0"/>
       <child  link="1"/>
       <origin rpy="0 0 0" xyz="0.0 -0.0 1.3351485137998912e-07" />
     <axis xyz="1 1 0"/>
       <limit effort="0.0" lower="-3.14159" upper="3.14159" velocity="0.0"/>
    </joint>
    <link name="1">
        <inertial>
            <origin xyz="0.0 0.0 0.06324320168360248" rpy="0 0 0"/>
            <mass value="1" />
            <inertia ixx="100" ixy="0" ixz="0" iyy="100" iyz="0" izz="100" />
        </inertial>
        <visual>
            <origin xyz="0.0 0.0 0.06324320168360248" rpy="0 0 0"/>
            <geometry>
                <box size="0.06269592435377819 0.17446402840593922 0.12648640336720496" />
            </geometry>
            <material name="Green">
                <color rgba="0 1 1 1"/>
            </material>
        </visual>
        <collision>
            <origin xyz="0.0 0.0 0.06324320168360248" rpy="0 0 0"/>
            <geometry>
                <box size="0.06269592435377819 0.17446402840593922 0.12648640336720496" />
            </geometry>
        </collision>
    </link>
    <joint name="Joint1_2" type="revolute">
       <parent link="1"/>
       <child  link="2"/>
       <origin rpy="0 0 0" xyz="0.0 0.08723201420296961 0.06324320168360248" />
     <axis xyz="1 0 1"/>
       <limit effort="0.0" lower="-3.14159" upper="3.14159" velocity="0.0"/>
    </joint>
    <link name="2">
        <inertial>
            <origin xyz="-0.0 -0.0029409056331078055 0.0" rpy="0 0 0"/>
            <mass value="1" />
            <inertia ixx="100" ixy="0" ixz="0" iyy="100" iyz="0" izz="100" />
        </inertial>
        <visual>
            <origin xyz="-0.0 -0.0029409056331078055 0.0" rpy="0 0 0"/>
            <geometry>
                <box size="-0.008112503379848422 -0.005881811266215611 -0.006945323713267376" />
            </geometry>
            <material name="Green">
                <color rgba="0 1 1 1"/>
            </material>
        </visual>
        <collision>
            <origin xyz="-0.0 -0.0029409056331078055 0.0" rpy="0 0 0"/>
            <geometry>
                <box size="-0.008112503379848422 -0.005881811266215611 -0.006945323713267376" />
            </geometry>
        </collision>
    </link>
    <joint name="Joint2_3" type="revolute">
       <parent link="2"/>
       <child  link="3"/>
       <origin rpy="0 0 0" xyz="-0.0 -0.0029409056331078055 -0.003472661856633688" />
     <axis xyz="1 1 0"/>
       <limit effort="0.0" lower="-3.14159" upper="3.14159" velocity="0.0"/>
    </joint>
    <link name="3">
        <inertial>
            <origin xyz="0.0 0.0 0.04401412799166655" rpy="0 0 0"/>
            <mass value="1" />
            <inertia ixx="100" ixy="0" ixz="0" iyy="100" iyz="0" izz="100" />
        </inertial>
        <visual>
            <origin xyz="0.0 0.0 0.04401412799166655" rpy="0 0 0"/>
            <geometry>
                <box size="0.4451360308361369 0.5184410714666885 0.0880282559833331" />
            </geometry>
            <material name="Green">
                <color rgba="0 1 1 1"/>
            </material>
        </visual>
        <collision>
            <origin xyz="0.0 0.0 0.04401412799166655" rpy="0 0 0"/>
            <geometry>
                <box size="0.4451360308361369 0.5184410714666885 0.0880282559833331" />
            </geometry>
        </collision>
    </link>
    <joint name="Joint3_4" type="revolute">
       <parent link="3"/>
       <child  link="4"/>
       <origin rpy="0 0 0" xyz="0.0 0.0 0.0880282559833331" />
     <axis xyz="1 1 0"/>
       <limit effort="0.0" lower="-3.14159" upper="3.14159" velocity="0.0"/>
    </joint>
    <link name="4">
        <inertial>
            <origin xyz="-0.0 0.0 0.002428839372003521" rpy="0 0 0"/>
            <mass value="1" />
            <inertia ixx="100" ixy="0" ixz="0" iyy="100" iyz="0" izz="100" />
        </inertial>
        <visual>
            <origin xyz="-0.0 0.0 0.002428839372003521" rpy="0 0 0"/>
            <geometry>
                <box size="-0.02582058942838423 0.002938783859670416 0.004857678744007042" />
            </geometry>
            <material name="Blue">
                <color rgba="0 1 0 1"/>
            </material>
        </visual>
        <collision>
            <origin xyz="-0.0 0.0 0.002428839372003521" rpy="0 0 0"/>
            <geometry>
                <box size="-0.02582058942838423 0.002938783859670416 0.004857678744007042" />
            </geometry>
        </collision>
    </link>
    <joint name="Joint3_6" type="revolute">
       <parent link="3"/>
       <child  link="6"/>
       <origin rpy="0 0 0" xyz="0.0 -0.25922053573334425 0.04401412799166655" />
     <axis xyz="1 0 1"/>
       <limit effort="0.0" lower="-3.14159" upper="3.14159" velocity="0.0"/>
    </joint>
    <link name="6">
        <inertial>
            <origin xyz="0.0 -0.13517785988610392 0.0" rpy="0 0 0"/>
            <mass value="1" />
            <inertia ixx="100" ixy="0" ixz="0" iyy="100" iyz="0" izz="100" />
        </inertial>
        <visual>
            <origin xyz="0.0 -0.13517785988610392 0.0" rpy="0 0 0"/>
            <geometry>
                <box size="0.39966534581190993 0.27035571977220785 0.11793405815157793" />
            </geometry>
            <material name="Green">
                <color rgba="0 1 1 1"/>
            </material>
        </visual>
        <collision>
            <origin xyz="0.0 -0.13517785988610392 0.0" rpy="0 0 0"/>
            <geometry>
                <box size="0.39966534581190993 0.27035571977220785 0.11793405815157793" />
            </geometry>
        </collision>
    </link>
    <joint name="Joint4_5" type="revolute">
       <parent link="4"/>
       <child  link="5"/>
       <origin rpy="0 0 0" xyz="-0.0 0.0 0.004857678744007042" />
     <axis xyz="1 1 0"/>
       <limit effort="0.0" lower="-3.14159" upper="3.14159" velocity="0.0"/>
    </joint>
    <link name="5">
        <inertial>
            <origin xyz="0.0 0.0 0.03404030344368707" rpy="0 0 0"/>
            <mass value="1" />
            <inertia ixx="100" ixy="0" ixz="0" iyy="100" iyz="0" izz="100" />
        </inertial>
        <visual>
            <origin xyz="0.0 0.0 0.03404030344368707" rpy="0 0 0"/>
            <geometry>
                <box size="0.14279873007465918 0.39895109193366496 0.06808060688737413" />
            </geometry>
            <material name="Green">
                <color rgba="0 1 1 1"/>
            </material>
        </visual>
        <collision>
            <origin xyz="0.0 0.0 0.03404030344368707" rpy="0 0 0"/>
            <geometry>
                <box size="0.14279873007465918 0.39895109193366496 0.06808060688737413" />
            </geometry>
        </collision>
    </link>
    <joint name="Joint6_7" type="revolute">
       <parent link="6"/>
       <child  link="7"/>
       <origin rpy="0 0 0" xyz="0.0 -0.27035571977220785 0.0" />
     <axis xyz="1 0 1"/>
       <limit effort="0.0" lower="-3.14159" upper="3.14159" velocity="0.0"/>
    </joint>
    <link name="7">
        <inertial>
            <origin xyz="0.0 -0.16707628340015696 0.0" rpy="0 0 0"/>
            <mass value="1" />
            <inertia ixx="100" ixy="0" ixz="0" iyy="100" iyz="0" izz="100" />
        </inertial>
        <visual>
            <origin xyz="0.0 -0.16707628340015696 0.0" rpy="0 0 0"/>
            <geometry>
                <box size="0.6100833309157436 0.3341525668003139 0.6374505528889234" />
            </geometry>
            <material name="Green">
                <color rgba="0 1 1 1"/>
            </material>
        </visual>
        <collision>
            <origin xyz="0.0 -0.16707628340015696 0.0" rpy="0 0 0"/>
            <geometry>
                <box size="0.6100833309157436 0.3341525668003139 0.6374505528889234" />
            </geometry>
        </collision>
    </link>
    <joint name="Joint5_8" type="revolute">
       <parent link="5"/>
       <child  link="8"/>
       <origin rpy="0 0 0" xyz="0.0 0.19947554596683248 0.03404030344368707" />
     <axis xyz="1 0 1"/>
       <limit effort="0.0" lower="-3.14159" upper="3.14159" velocity="0.0"/>
    </joint>
    <link name="8">
        <inertial>
            <origin xyz="0.0 0.2882195246775098 0.0" rpy="0 0 0"/>
            <mass value="1" />
            <inertia ixx="100" ixy="0" ixz="0" iyy="100" iyz="0" izz="100" />
        </inertial>
        <visual>
            <origin xyz="0.0 0.2882195246775098 0.0" rpy="0 0 0"/>
            <geometry>
                <box size="0.6381432749979006 0.5764390493550196 0.14728606059385313" />
            </geometry>
            <material name="Green">
                <color rgba="0 1 1 1"/>
            </material>
        </visual>
        <collision>
            <origin xyz="0.0 0.2882195246775098 0.0" rpy="0 0 0"/>
            <geometry>
                <box size="0.6381432749979006 0.5764390493550196 0.14728606059385313" />
            </geometry>
        </collision>
    </link>
    <joint name="Joint8_9" type="revolute">
       <parent link="8"/>
       <child  link="9"/>
       <origin rpy="0 0 0" xyz="-0.3190716374989503 0.2882195246775098 0.0" />
     <axis xyz="0 1 1"/>
       <limit effort="0.0" lower="-3.14159" upper="3.14159" velocity="0.0"/>
    </joint>
    <link name="9">
        <inertial>
            <origin xyz="-0.23517652184137983 0.0 0.0" rpy="0 0 0"/>
            <mass value="1" />
            <inertia ixx="100" ixy="0" ixz="0" iyy="100" iyz="0" izz="100" />
        </inertial>
        <visual>
            <origin xyz="-0.23517652184137983 0.0 0.0" rpy="0 0 0"/>
            <geometry>
                <box size="0.47035304368275965 0.11513716699972482 0.25028714773476896" />
            </geometry>
            <material name="Green">
                <color rgba="0 1 1 1"/>
            </material>
        </visual>
        <collision>
            <origin xyz="-0.23517652184137983 0.0 0.0" rpy="0 0 0"/>
            <geometry>
                <box size="0.47035304368275965 0.11513716699972482 0.25028714773476896" />
            </geometry>
        </collision>
    </link>
</robot>