<robot name = "robot">
    <link name="0">
        <inertial>
            <origin xyz="0 0 0" rpy="0 0 0"/>
            <mass value="1" />
            <inertia ixx="100" ixy="0" ixz="0" iyy="100" iyz="0" izz="100" />
        </inertial>
        <visual>
            <origin xyz="0 0 0" rpy="0 0 0"/>
            <geometry>
                <box size="0.42309269198280375 0.20010762617802522 0.14038470528853425" />
            </geometry>
            <material name="Cyan">
                <color rgba="0 1 0 1"/>
            </material>
        </visual>
        <collision>
            <origin xyz="0 0 0" rpy="0 0 0"/>
            <geometry>
                <box size="0.42309269198280375 0.20010762617802522 0.14038470528853425" />
            </geometry>
        </collision>
    </link>
    <joint name="Joint0_1" type="revolute">
       <parent link="0"/>
       <child  link="1"/>
       <origin rpy="0 0 0" xyz="0.0 0.0 0.07019235264426713" />
     <axis xyz="1 1 0"/>
       <limit effort="0.0" lower="-3.14159" upper="3.14159" velocity="0.0"/>
    </joint>
    <link name="1">
        <inertial>
            <origin xyz="0.0 0.0 0.008389349135968348" rpy="0 0 0"/>
            <mass value="1" />
            <inertia ixx="100" ixy="0" ixz="0" iyy="100" iyz="0" izz="100" />
        </inertial>
        <visual>
            <origin xyz="0.0 0.0 0.008389349135968348" rpy="0 0 0"/>
            <geometry>
                <box size="0.39066940923529764 0.1439308065036748 0.016778698271936697" />
            </geometry>
            <material name="Blue">
                <color rgba="0 1 0 1"/>
            </material>
        </visual>
        <collision>
            <origin xyz="0.0 0.0 0.008389349135968348" rpy="0 0 0"/>
            <geometry>
                <box size="0.39066940923529764 0.1439308065036748 0.016778698271936697" />
            </geometry>
        </collision>
    </link>
    <joint name="Joint1_2" type="revolute">
       <parent link="1"/>
       <child  link="2"/>
       <origin rpy="0 0 0" xyz="0.0 0.0 0.016778698271936697" />
     <axis xyz="1 1 0"/>
       <limit effort="0.0" lower="-3.14159" upper="3.14159" velocity="0.0"/>
    </joint>
    <link name="2">
        <inertial>
            <origin xyz="0.0 0.0 0.3125109557369089" rpy="0 0 0"/>
            <mass value="1" />
            <inertia ixx="100" ixy="0" ixz="0" iyy="100" iyz="0" izz="100" />
        </inertial>
        <visual>
            <origin xyz="0.0 0.0 0.3125109557369089" rpy="0 0 0"/>
            <geometry>
                <box size="0.5845127004627195 0.10831827748949358 0.6250219114738178" />
            </geometry>
            <material name="Blue">
                <color rgba="0 1 0 1"/>
            </material>
        </visual>
        <collision>
            <origin xyz="0.0 0.0 0.3125109557369089" rpy="0 0 0"/>
            <geometry>
                <box size="0.5845127004627195 0.10831827748949358 0.6250219114738178" />
            </geometry>
        </collision>
    </link>
    <joint name="Joint1_3" type="revolute">
       <parent link="1"/>
       <child  link="3"/>
       <origin rpy="0 0 0" xyz="0.19533470461764882 0.0 0.008389349135968348" />
     <axis xyz="0 1 1"/>
       <limit effort="0.0" lower="-3.14159" upper="3.14159" velocity="0.0"/>
    </joint>
    <link name="3">
        <inertial>
            <origin xyz="0.09273226136553038 0.0 0.0" rpy="0 0 0"/>
            <mass value="1" />
            <inertia ixx="100" ixy="0" ixz="0" iyy="100" iyz="0" izz="100" />
        </inertial>
        <visual>
            <origin xyz="0.09273226136553038 0.0 0.0" rpy="0 0 0"/>
            <geometry>
                <box size="0.18546452273106076 0.3434899072064213 0.22949912099338762" />
            </geometry>
            <material name="Blue">
                <color rgba="0 1 0 1"/>
            </material>
        </visual>
        <collision>
            <origin xyz="0.09273226136553038 0.0 0.0" rpy="0 0 0"/>
            <geometry>
                <box size="0.18546452273106076 0.3434899072064213 0.22949912099338762" />
            </geometry>
        </collision>
    </link>
</robot>