<robot name = "robot">
    <link name="0">
        <inertial>
            <origin xyz="0 0 0" rpy="0 0 0"/>
            <mass value="1" />
            <inertia ixx="100" ixy="0" ixz="0" iyy="100" iyz="0" izz="100" />
        </inertial>
        <visual>
            <origin xyz="0 0 0" rpy="0 0 0"/>
            <geometry>
                <box size="-7.957561140384703e-10 -9.912043057367515e-08 3.6697714892901975e-08" />
            </geometry>
            <material name="Cyan">
                <color rgba="0 1 0 1"/>
            </material>
        </visual>
        <collision>
            <origin xyz="0 0 0" rpy="0 0 0"/>
            <geometry>
                <box size="-7.957561140384703e-10 -9.912043057367515e-08 3.6697714892901975e-08" />
            </geometry>
        </collision>
    </link>
    <joint name="Joint0_1" type="revolute">
       <parent link="0"/>
       <child  link="1"/>
       <origin rpy="0 0 0" xyz="-0.0 -0.0 1.8348857446450988e-08" />
     <axis xyz="0 1 0"/>
       <limit effort="0.0" lower="-3.14159" upper="3.14159" velocity="0.0"/>
    </joint>
    <link name="1">
        <inertial>
            <origin xyz="0.0 0.0 -0.00013164691944726677" rpy="0 0 0"/>
            <mass value="1" />
            <inertia ixx="100" ixy="0" ixz="0" iyy="100" iyz="0" izz="100" />
        </inertial>
        <visual>
            <origin xyz="0.0 0.0 -0.00013164691944726677" rpy="0 0 0"/>
            <geometry>
                <box size="0.00015188172652932173 3.218290685485328e-05 -0.00026329383889453354" />
            </geometry>
            <material name="Blue">
                <color rgba="0 1 0 1"/>
            </material>
        </visual>
        <collision>
            <origin xyz="0.0 0.0 -0.00013164691944726677" rpy="0 0 0"/>
            <geometry>
                <box size="0.00015188172652932173 3.218290685485328e-05 -0.00026329383889453354" />
            </geometry>
        </collision>
    </link>
    <joint name="Joint1_2" type="revolute">
       <parent link="1"/>
       <child  link="2"/>
       <origin rpy="0 0 0" xyz="0.0 0.0 -0.00026329383889453354" />
     <axis xyz="0 1 0"/>
       <limit effort="0.0" lower="-3.14159" upper="3.14159" velocity="0.0"/>
    </joint>
    <link name="2">
        <inertial>
            <origin xyz="0.0 0.0 0.11012850376207317" rpy="0 0 0"/>
            <mass value="1" />
            <inertia ixx="100" ixy="0" ixz="0" iyy="100" iyz="0" izz="100" />
        </inertial>
        <visual>
            <origin xyz="0.0 0.0 0.11012850376207317" rpy="0 0 0"/>
            <geometry>
                <box size="0.6119524305867508 0.1020506166527261 0.22025700752414634" />
            </geometry>
            <material name="Blue">
                <color rgba="0 1 0 1"/>
            </material>
        </visual>
        <collision>
            <origin xyz="0.0 0.0 0.11012850376207317" rpy="0 0 0"/>
            <geometry>
                <box size="0.6119524305867508 0.1020506166527261 0.22025700752414634" />
            </geometry>
        </collision>
    </link>
    <joint name="Joint1_4" type="revolute">
       <parent link="1"/>
       <child  link="4"/>
       <origin rpy="0 0 0" xyz="7.594086326466087e-05 0.0 -0.00013164691944726677" />
     <axis xyz="1 0 0"/>
       <limit effort="0.0" lower="-3.14159" upper="3.14159" velocity="0.0"/>
    </joint>
    <link name="4">
        <inertial>
            <origin xyz="0.0002312835069182595 -0.0 0.0" rpy="0 0 0"/>
            <mass value="1" />
            <inertia ixx="100" ixy="0" ixz="0" iyy="100" iyz="0" izz="100" />
        </inertial>
        <visual>
            <origin xyz="0.0002312835069182595 -0.0 0.0" rpy="0 0 0"/>
            <geometry>
                <box size="0.000462567013836519 -0.0011845768225131682 0.005341609056697958" />
            </geometry>
            <material name="Blue">
                <color rgba="0 1 0 1"/>
            </material>
        </visual>
        <collision>
            <origin xyz="0.0002312835069182595 -0.0 0.0" rpy="0 0 0"/>
            <geometry>
                <box size="0.000462567013836519 -0.0011845768225131682 0.005341609056697958" />
            </geometry>
        </collision>
    </link>
    <joint name="Joint2_3" type="revolute">
       <parent link="2"/>
       <child  link="3"/>
       <origin rpy="0 0 0" xyz="0.3059762152933754 0.0 0.11012850376207317" />
     <axis xyz="1 0 0"/>
       <limit effort="0.0" lower="-3.14159" upper="3.14159" velocity="0.0"/>
    </joint>
    <link name="3">
        <inertial>
            <origin xyz="0.32170843754457346 0.0 0.0" rpy="0 0 0"/>
            <mass value="1" />
            <inertia ixx="100" ixy="0" ixz="0" iyy="100" iyz="0" izz="100" />
        </inertial>
        <visual>
            <origin xyz="0.32170843754457346 0.0 0.0" rpy="0 0 0"/>
            <geometry>
                <box size="0.6434168750891469 0.10337052964380689 0.1665470828551218" />
            </geometry>
            <material name="Blue">
                <color rgba="0 1 0 1"/>
            </material>
        </visual>
        <collision>
            <origin xyz="0.32170843754457346 0.0 0.0" rpy="0 0 0"/>
            <geometry>
                <box size="0.6434168750891469 0.10337052964380689 0.1665470828551218" />
            </geometry>
        </collision>
    </link>
    <joint name="Joint2_5" type="revolute">
       <parent link="2"/>
       <child  link="5"/>
       <origin rpy="0 0 0" xyz="-0.3059762152933754 0.0 0.11012850376207317" />
     <axis xyz="1 0 0"/>
       <limit effort="0.0" lower="-3.14159" upper="3.14159" velocity="0.0"/>
    </joint>
    <link name="5">
        <inertial>
            <origin xyz="-4.4140634046548325e-05 -0.0 0.0" rpy="0 0 0"/>
            <mass value="1" />
            <inertia ixx="100" ixy="0" ixz="0" iyy="100" iyz="0" izz="100" />
        </inertial>
        <visual>
            <origin xyz="-4.4140634046548325e-05 -0.0 0.0" rpy="0 0 0"/>
            <geometry>
                <box size="8.828126809309665e-05 -7.793601065264045e-05 0.0002532778218332538" />
            </geometry>
            <material name="Blue">
                <color rgba="0 1 0 1"/>
            </material>
        </visual>
        <collision>
            <origin xyz="-4.4140634046548325e-05 -0.0 0.0" rpy="0 0 0"/>
            <geometry>
                <box size="8.828126809309665e-05 -7.793601065264045e-05 0.0002532778218332538" />
            </geometry>
        </collision>
    </link>
    <joint name="Joint3_6" type="revolute">
       <parent link="3"/>
       <child  link="6"/>
       <origin rpy="0 0 0" xyz="0.32170843754457346 -0.05168526482190344 0.0" />
     <axis xyz="0 1 0"/>
       <limit effort="0.0" lower="-3.14159" upper="3.14159" velocity="0.0"/>
    </joint>
    <link name="6">
        <inertial>
            <origin xyz="-0.0 0.0017705355044400847 0.0" rpy="0 0 0"/>
            <mass value="1" />
            <inertia ixx="100" ixy="0" ixz="0" iyy="100" iyz="0" izz="100" />
        </inertial>
        <visual>
            <origin xyz="-0.0 0.0017705355044400847 0.0" rpy="0 0 0"/>
            <geometry>
                <box size="-0.01370771755238275 -0.0035410710088801694 -0.017256700662960738" />
            </geometry>
            <material name="Green">
                <color rgba="0 1 1 1"/>
            </material>
        </visual>
        <collision>
            <origin xyz="-0.0 0.0017705355044400847 0.0" rpy="0 0 0"/>
            <geometry>
                <box size="-0.01370771755238275 -0.0035410710088801694 -0.017256700662960738" />
            </geometry>
        </collision>
    </link>
    <joint name="Joint3_14" type="revolute">
       <parent link="3"/>
       <child  link="14"/>
       <origin rpy="0 0 0" xyz="0.6434168750891469 0.0 0.0" />
     <axis xyz="1 0 0"/>
       <limit effort="0.0" lower="-3.14159" upper="3.14159" velocity="0.0"/>
    </joint>
    <link name="14">
        <inertial>
            <origin xyz="8.491174381473077e-05 -0.0 0.0" rpy="0 0 0"/>
            <mass value="1" />
            <inertia ixx="100" ixy="0" ixz="0" iyy="100" iyz="0" izz="100" />
        </inertial>
        <visual>
            <origin xyz="8.491174381473077e-05 -0.0 0.0" rpy="0 0 0"/>
            <geometry>
                <box size="0.00016982348762946154 -1.1450119285176079e-05 -4.580716262918794e-05" />
            </geometry>
            <material name="Blue">
                <color rgba="0 1 0 1"/>
            </material>
        </visual>
        <collision>
            <origin xyz="8.491174381473077e-05 -0.0 0.0" rpy="0 0 0"/>
            <geometry>
                <box size="0.00016982348762946154 -1.1450119285176079e-05 -4.580716262918794e-05" />
            </geometry>
        </collision>
    </link>
    <joint name="Joint6_7" type="revolute">
       <parent link="6"/>
       <child  link="7"/>
       <origin rpy="0 0 0" xyz="-0.0 0.0017705355044400847 -0.008628350331480369" />
     <axis xyz="0 1 0"/>
       <limit effort="0.0" lower="-3.14159" upper="3.14159" velocity="0.0"/>
    </joint>
    <link name="7">
        <inertial>
            <origin xyz="0.0 0.0 0.2824159183622673" rpy="0 0 0"/>
            <mass value="1" />
            <inertia ixx="100" ixy="0" ixz="0" iyy="100" iyz="0" izz="100" />
        </inertial>
        <visual>
            <origin xyz="0.0 0.0 0.2824159183622673" rpy="0 0 0"/>
            <geometry>
                <box size="0.4666750972140333 0.11643507879151559 0.5648318367245346" />
            </geometry>
            <material name="Blue">
                <color rgba="0 1 0 1"/>
            </material>
        </visual>
        <collision>
            <origin xyz="0.0 0.0 0.2824159183622673" rpy="0 0 0"/>
            <geometry>
                <box size="0.4666750972140333 0.11643507879151559 0.5648318367245346" />
            </geometry>
        </collision>
    </link>
    <joint name="Joint7_8" type="revolute">
       <parent link="7"/>
       <child  link="8"/>
       <origin rpy="0 0 0" xyz="0.0 0.0 0.5648318367245346" />
     <axis xyz="0 1 0"/>
       <limit effort="0.0" lower="-3.14159" upper="3.14159" velocity="0.0"/>
    </joint>
    <link name="8">
        <inertial>
            <origin xyz="-0.0 -0.0 0.006370337289873395" rpy="0 0 0"/>
            <mass value="1" />
            <inertia ixx="100" ixy="0" ixz="0" iyy="100" iyz="0" izz="100" />
        </inertial>
        <visual>
            <origin xyz="-0.0 -0.0 0.006370337289873395" rpy="0 0 0"/>
            <geometry>
                <box size="-0.0011981828425236577 -0.009840078460390375 0.01274067457974679" />
            </geometry>
            <material name="Blue">
                <color rgba="0 1 0 1"/>
            </material>
        </visual>
        <collision>
            <origin xyz="-0.0 -0.0 0.006370337289873395" rpy="0 0 0"/>
            <geometry>
                <box size="-0.0011981828425236577 -0.009840078460390375 0.01274067457974679" />
            </geometry>
        </collision>
    </link>
    <joint name="Joint8_9" type="revolute">
       <parent link="8"/>
       <child  link="9"/>
       <origin rpy="0 0 0" xyz="-0.0 -0.004920039230195188 0.006370337289873395" />
     <axis xyz="0 1 0"/>
       <limit effort="0.0" lower="-3.14159" upper="3.14159" velocity="0.0"/>
    </joint>
    <link name="9">
        <inertial>
            <origin xyz="0.0 0.29904551754843756 0.0" rpy="0 0 0"/>
            <mass value="1" />
            <inertia ixx="100" ixy="0" ixz="0" iyy="100" iyz="0" izz="100" />
        </inertial>
        <visual>
            <origin xyz="0.0 0.29904551754843756 0.0" rpy="0 0 0"/>
            <geometry>
                <box size="0.38137140347183507 0.5980910350968751 0.5589702388248055" />
            </geometry>
            <material name="Blue">
                <color rgba="0 1 0 1"/>
            </material>
        </visual>
        <collision>
            <origin xyz="0.0 0.29904551754843756 0.0" rpy="0 0 0"/>
            <geometry>
                <box size="0.38137140347183507 0.5980910350968751 0.5589702388248055" />
            </geometry>
        </collision>
    </link>
    <joint name="Joint8_10" type="revolute">
       <parent link="8"/>
       <child  link="10"/>
       <origin rpy="0 0 0" xyz="-0.0 0.004920039230195188 0.006370337289873395" />
     <axis xyz="0 1 0"/>
       <limit effort="0.0" lower="-3.14159" upper="3.14159" velocity="0.0"/>
    </joint>
    <link name="10">
        <inertial>
            <origin xyz="0.0 -0.00014073566299949383 0.0" rpy="0 0 0"/>
            <mass value="1" />
            <inertia ixx="100" ixy="0" ixz="0" iyy="100" iyz="0" izz="100" />
        </inertial>
        <visual>
            <origin xyz="0.0 -0.00014073566299949383 0.0" rpy="0 0 0"/>
            <geometry>
                <box size="7.952996257971437e-05 0.00028147132599898767 3.650518496695395e-05" />
            </geometry>
            <material name="Blue">
                <color rgba="0 1 0 1"/>
            </material>
        </visual>
        <collision>
            <origin xyz="0.0 -0.00014073566299949383 0.0" rpy="0 0 0"/>
            <geometry>
                <box size="7.952996257971437e-05 0.00028147132599898767 3.650518496695395e-05" />
            </geometry>
        </collision>
    </link>
    <joint name="Joint8_12" type="revolute">
       <parent link="8"/>
       <child  link="12"/>
       <origin rpy="0 0 0" xyz="0.0005990914212618289 -0.0 0.006370337289873395" />
     <axis xyz="1 0 0"/>
       <limit effort="0.0" lower="-3.14159" upper="3.14159" velocity="0.0"/>
    </joint>
    <link name="12">
        <inertial>
            <origin xyz="0.006352555787347639 0.0 0.0" rpy="0 0 0"/>
            <mass value="1" />
            <inertia ixx="100" ixy="0" ixz="0" iyy="100" iyz="0" izz="100" />
        </inertial>
        <visual>
            <origin xyz="0.006352555787347639 0.0 0.0" rpy="0 0 0"/>
            <geometry>
                <box size="-0.012705111574695277 0.002469827620825492 0.00845428735717365" />
            </geometry>
            <material name="Blue">
                <color rgba="0 1 0 1"/>
            </material>
        </visual>
        <collision>
            <origin xyz="0.006352555787347639 0.0 0.0" rpy="0 0 0"/>
            <geometry>
                <box size="-0.012705111574695277 0.002469827620825492 0.00845428735717365" />
            </geometry>
        </collision>
    </link>
    <joint name="Joint9_11" type="revolute">
       <parent link="9"/>
       <child  link="11"/>
       <origin rpy="0 0 0" xyz="0.0 0.29904551754843756 0.2794851194124027" />
     <axis xyz="0 1 0"/>
       <limit effort="0.0" lower="-3.14159" upper="3.14159" velocity="0.0"/>
    </joint>
    <link name="11">
        <inertial>
            <origin xyz="0.0 -0.0 0.004725488483582147" rpy="0 0 0"/>
            <mass value="1" />
            <inertia ixx="100" ixy="0" ixz="0" iyy="100" iyz="0" izz="100" />
        </inertial>
        <visual>
            <origin xyz="0.0 -0.0 0.004725488483582147" rpy="0 0 0"/>
            <geometry>
                <box size="0.011233800286091621 -0.006704438401225162 0.009450976967164295" />
            </geometry>
            <material name="Blue">
                <color rgba="0 1 0 1"/>
            </material>
        </visual>
        <collision>
            <origin xyz="0.0 -0.0 0.004725488483582147" rpy="0 0 0"/>
            <geometry>
                <box size="0.011233800286091621 -0.006704438401225162 0.009450976967164295" />
            </geometry>
        </collision>
    </link>
    <joint name="Joint9_13" type="revolute">
       <parent link="9"/>
       <child  link="13"/>
       <origin rpy="0 0 0" xyz="0.0 0.29904551754843756 -0.2794851194124027" />
     <axis xyz="0 1 0"/>
       <limit effort="0.0" lower="-3.14159" upper="3.14159" velocity="0.0"/>
    </joint>
    <link name="13">
        <inertial>
            <origin xyz="-0.0 -0.0 -0.011040619260015304" rpy="0 0 0"/>
            <mass value="1" />
            <inertia ixx="100" ixy="0" ixz="0" iyy="100" iyz="0" izz="100" />
        </inertial>
        <visual>
            <origin xyz="-0.0 -0.0 -0.011040619260015304" rpy="0 0 0"/>
            <geometry>
                <box size="-0.0006894907390168105 -0.0013649808314263356 0.02208123852003061" />
            </geometry>
            <material name="Blue">
                <color rgba="0 1 0 1"/>
            </material>
        </visual>
        <collision>
            <origin xyz="-0.0 -0.0 -0.011040619260015304" rpy="0 0 0"/>
            <geometry>
                <box size="-0.0006894907390168105 -0.0013649808314263356 0.02208123852003061" />
            </geometry>
        </collision>
    </link>
</robot>