<robot name = "robot">
    <link name="Back0">
        <inertial>
            <origin xyz="0 0 0" rpy="0 0 0"/>
            <mass value="1" />
            <inertia ixx="100" ixy="0" ixz="0" iyy="100" iyz="0" izz="100" />
        </inertial>
        <visual>
            <origin xyz="0 0 0" rpy="0 0 0"/>
            <geometry>
                <box size="0.34889728844377343 0.5524828620342417 0.31873923668167986" />
            </geometry>
            <material name="Blue">
                <color rgba="0 1 0 1"/>
            </material>
        </visual>
        <collision>
            <origin xyz="0 0 0" rpy="0 0 0"/>
            <geometry>
                <box size="0.34889728844377343 0.5524828620342417 0.31873923668167986" />
            </geometry>
        </collision>
    </link>
    <joint name="Back0_Back1" type="revolute">
       <parent link="Back0"/>
       <child  link="Back1"/>
       <origin rpy="0 0 0" xyz="0 -0.27624143101712084 0.0" />
     <axis xyz="0 0 1"/>
       <limit effort="0.0" lower="-3.14159" upper="3.14159" velocity="0.0"/>
    </joint>
    <link name="Back1">
        <inertial>
            <origin xyz="0 -0.08126960082506288 -0.15" rpy="0 0 0"/>
            <mass value="1" />
            <inertia ixx="100" ixy="0" ixz="0" iyy="100" iyz="0" izz="100" />
        </inertial>
        <visual>
            <origin xyz="0 -0.08126960082506288 -0.15" rpy="0 0 0"/>
            <geometry>
                <box size="0.44229336420901527 0.16253920165012575 0.21924634137232002" />
            </geometry>
            <material name="Blue">
                <color rgba="0 1 0 1"/>
            </material>
        </visual>
        <collision>
            <origin xyz="0 -0.08126960082506288 -0.15" rpy="0 0 0"/>
            <geometry>
                <box size="0.44229336420901527 0.16253920165012575 0.21924634137232002" />
            </geometry>
        </collision>
    </link>
    <joint name="Back1_Back2" type="revolute">
       <parent link="Back1"/>
       <child  link="Back2"/>
       <origin rpy="0 0 0" xyz="0 -0.16253920165012575 0.0" />
     <axis xyz="0 0 1"/>
       <limit effort="0.0" lower="-3.14159" upper="3.14159" velocity="0.0"/>
    </joint>
    <link name="Back2">
        <inertial>
            <origin xyz="0 -0.12453973318405287 -0.15" rpy="0 0 0"/>
            <mass value="1" />
            <inertia ixx="100" ixy="0" ixz="0" iyy="100" iyz="0" izz="100" />
        </inertial>
        <visual>
            <origin xyz="0 -0.12453973318405287 -0.15" rpy="0 0 0"/>
            <geometry>
                <box size="0.33445181344268826 0.24907946636810574 0.6248506489317329" />
            </geometry>
            <material name="Blue">
                <color rgba="0 1 0 1"/>
            </material>
        </visual>
        <collision>
            <origin xyz="0 -0.12453973318405287 -0.15" rpy="0 0 0"/>
            <geometry>
                <box size="0.33445181344268826 0.24907946636810574 0.6248506489317329" />
            </geometry>
        </collision>
    </link>
    <joint name="Back2_Back3" type="revolute">
       <parent link="Back2"/>
       <child  link="Back3"/>
       <origin rpy="0 0 0" xyz="0 -0.24907946636810574 0.0" />
     <axis xyz="1 0 0"/>
       <limit effort="0.0" lower="-3.14159" upper="3.14159" velocity="0.0"/>
    </joint>
    <link name="Back3">
        <inertial>
            <origin xyz="0 -0.190998277966346 -0.15" rpy="0 0 0"/>
            <mass value="1" />
            <inertia ixx="100" ixy="0" ixz="0" iyy="100" iyz="0" izz="100" />
        </inertial>
        <visual>
            <origin xyz="0 -0.190998277966346 -0.15" rpy="0 0 0"/>
            <geometry>
                <box size="0.19745104306769787 0.381996555932692 0.2931745755569982" />
            </geometry>
            <material name="Green">
                <color rgba="0 1 1 1"/>
            </material>
        </visual>
        <collision>
            <origin xyz="0 -0.190998277966346 -0.15" rpy="0 0 0"/>
            <geometry>
                <box size="0.19745104306769787 0.381996555932692 0.2931745755569982" />
            </geometry>
        </collision>
    </link>
    <joint name="Back3_Back4" type="revolute">
       <parent link="Back3"/>
       <child  link="Back4"/>
       <origin rpy="0 0 0" xyz="0 -0.381996555932692 0.0" />
     <axis xyz="0 0 1"/>
       <limit effort="0.0" lower="-3.14159" upper="3.14159" velocity="0.0"/>
    </joint>
    <link name="Back4">
        <inertial>
            <origin xyz="0 -0.030149188929392206 -0.15" rpy="0 0 0"/>
            <mass value="1" />
            <inertia ixx="100" ixy="0" ixz="0" iyy="100" iyz="0" izz="100" />
        </inertial>
        <visual>
            <origin xyz="0 -0.030149188929392206 -0.15" rpy="0 0 0"/>
            <geometry>
                <box size="0.42304675443486583 0.06029837785878441 0.16118381356109995" />
            </geometry>
            <material name="Green">
                <color rgba="0 1 1 1"/>
            </material>
        </visual>
        <collision>
            <origin xyz="0 -0.030149188929392206 -0.15" rpy="0 0 0"/>
            <geometry>
                <box size="0.42304675443486583 0.06029837785878441 0.16118381356109995" />
            </geometry>
        </collision>
    </link>
    <joint name="Back4_Back5" type="revolute">
       <parent link="Back4"/>
       <child  link="Back5"/>
       <origin rpy="0 0 0" xyz="0 -0.06029837785878441 0.0" />
     <axis xyz="0 0 1"/>
       <limit effort="0.0" lower="-3.14159" upper="3.14159" velocity="0.0"/>
    </joint>
    <link name="Back5">
        <inertial>
            <origin xyz="0 -0.11377205580531655 -0.15" rpy="0 0 0"/>
            <mass value="1" />
            <inertia ixx="100" ixy="0" ixz="0" iyy="100" iyz="0" izz="100" />
        </inertial>
        <visual>
            <origin xyz="0 -0.11377205580531655 -0.15" rpy="0 0 0"/>
            <geometry>
                <box size="0.2106812514628546 0.2275441116106331 0.5049405678269879" />
            </geometry>
            <material name="Green">
                <color rgba="0 1 1 1"/>
            </material>
        </visual>
        <collision>
            <origin xyz="0 -0.11377205580531655 -0.15" rpy="0 0 0"/>
            <geometry>
                <box size="0.2106812514628546 0.2275441116106331 0.5049405678269879" />
            </geometry>
        </collision>
    </link>
    <joint name="Back5_Back6" type="revolute">
       <parent link="Back5"/>
       <child  link="Back6"/>
       <origin rpy="0 0 0" xyz="0 -0.2275441116106331 0.0" />
     <axis xyz="1 0 0"/>
       <limit effort="0.0" lower="-3.14159" upper="3.14159" velocity="0.0"/>
    </joint>
    <link name="Back6">
        <inertial>
            <origin xyz="0 -0.23438441272886562 -0.15" rpy="0 0 0"/>
            <mass value="1" />
            <inertia ixx="100" ixy="0" ixz="0" iyy="100" iyz="0" izz="100" />
        </inertial>
        <visual>
            <origin xyz="0 -0.23438441272886562 -0.15" rpy="0 0 0"/>
            <geometry>
                <box size="0.4066438002398369 0.46876882545773124 0.2753514505822974" />
            </geometry>
            <material name="Blue">
                <color rgba="0 1 0 1"/>
            </material>
        </visual>
        <collision>
            <origin xyz="0 -0.23438441272886562 -0.15" rpy="0 0 0"/>
            <geometry>
                <box size="0.4066438002398369 0.46876882545773124 0.2753514505822974" />
            </geometry>
        </collision>
    </link>
    <joint name="Back6_Back7" type="revolute">
       <parent link="Back6"/>
       <child  link="Back7"/>
       <origin rpy="0 0 0" xyz="0 -0.46876882545773124 0.0" />
     <axis xyz="0 0 1"/>
       <limit effort="0.0" lower="-3.14159" upper="3.14159" velocity="0.0"/>
    </joint>
    <link name="Back7">
        <inertial>
            <origin xyz="0 -0.25511760123738714 -0.15" rpy="0 0 0"/>
            <mass value="1" />
            <inertia ixx="100" ixy="0" ixz="0" iyy="100" iyz="0" izz="100" />
        </inertial>
        <visual>
            <origin xyz="0 -0.25511760123738714 -0.15" rpy="0 0 0"/>
            <geometry>
                <box size="0.17646319881730987 0.5102352024747743 0.46918916204958727" />
            </geometry>
            <material name="Blue">
                <color rgba="0 1 0 1"/>
            </material>
        </visual>
        <collision>
            <origin xyz="0 -0.25511760123738714 -0.15" rpy="0 0 0"/>
            <geometry>
                <box size="0.17646319881730987 0.5102352024747743 0.46918916204958727" />
            </geometry>
        </collision>
    </link>
    <joint name="Back7_Back8" type="revolute">
       <parent link="Back7"/>
       <child  link="Back8"/>
       <origin rpy="0 0 0" xyz="0 -0.5102352024747743 0.0" />
     <axis xyz="0 0 1"/>
       <limit effort="0.0" lower="-3.14159" upper="3.14159" velocity="0.0"/>
    </joint>
    <link name="Back8">
        <inertial>
            <origin xyz="0 -0.3122385360455815 -0.15" rpy="0 0 0"/>
            <mass value="1" />
            <inertia ixx="100" ixy="0" ixz="0" iyy="100" iyz="0" izz="100" />
        </inertial>
        <visual>
            <origin xyz="0 -0.3122385360455815 -0.15" rpy="0 0 0"/>
            <geometry>
                <box size="0.6156704003584799 0.624477072091163 0.3477944892744054" />
            </geometry>
            <material name="Green">
                <color rgba="0 1 1 1"/>
            </material>
        </visual>
        <collision>
            <origin xyz="0 -0.3122385360455815 -0.15" rpy="0 0 0"/>
            <geometry>
                <box size="0.6156704003584799 0.624477072091163 0.3477944892744054" />
            </geometry>
        </collision>
    </link>
    <joint name="Back8_Back9" type="revolute">
       <parent link="Back8"/>
       <child  link="Back9"/>
       <origin rpy="0 0 0" xyz="0 -0.624477072091163 0.0" />
     <axis xyz="1 0 0"/>
       <limit effort="0.0" lower="-3.14159" upper="3.14159" velocity="0.0"/>
    </joint>
    <link name="Back9">
        <inertial>
            <origin xyz="0 -0.08889256911437424 -0.15" rpy="0 0 0"/>
            <mass value="1" />
            <inertia ixx="100" ixy="0" ixz="0" iyy="100" iyz="0" izz="100" />
        </inertial>
        <visual>
            <origin xyz="0 -0.08889256911437424 -0.15" rpy="0 0 0"/>
            <geometry>
                <box size="0.3287813940604739 0.17778513822874847 0.3250072802012345" />
            </geometry>
            <material name="Blue">
                <color rgba="0 1 0 1"/>
            </material>
        </visual>
        <collision>
            <origin xyz="0 -0.08889256911437424 -0.15" rpy="0 0 0"/>
            <geometry>
                <box size="0.3287813940604739 0.17778513822874847 0.3250072802012345" />
            </geometry>
        </collision>
    </link>
</robot>