<robot name = "robot">
    <link name="0">
        <inertial>
            <origin xyz="0 0 0" rpy="0 0 0"/>
            <mass value="1" />
            <inertia ixx="100" ixy="0" ixz="0" iyy="100" iyz="0" izz="100" />
        </inertial>
        <visual>
            <origin xyz="0 0 0" rpy="0 0 0"/>
            <geometry>
                <box size="0.23544277669496202 0.12879527345217423 0.4270277283226853" />
            </geometry>
            <material name="Cyan">
                <color rgba="0 1 1 1"/>
            </material>
        </visual>
        <collision>
            <origin xyz="0 0 0" rpy="0 0 0"/>
            <geometry>
                <box size="0.23544277669496202 0.12879527345217423 0.4270277283226853" />
            </geometry>
        </collision>
    </link>
    <joint name="Joint0_1" type="revolute">
       <parent link="0"/>
       <child  link="1"/>
       <origin rpy="0 0 0" xyz="0.0 0.0 0.21351386416134266" />
     <axis xyz="1 1 0"/>
       <limit effort="0.0" lower="-3.14159" upper="3.14159" velocity="0.0"/>
    </joint>
    <link name="1">
        <inertial>
            <origin xyz="0.0 0.0 0.12507728437566967" rpy="0 0 0"/>
            <mass value="1" />
            <inertia ixx="100" ixy="0" ixz="0" iyy="100" iyz="0" izz="100" />
        </inertial>
        <visual>
            <origin xyz="0.0 0.0 0.12507728437566967" rpy="0 0 0"/>
            <geometry>
                <box size="0.5825203289501653 0.4567255278517912 0.25015456875133935" />
            </geometry>
            <material name="Green">
                <color rgba="0 1 1 1"/>
            </material>
        </visual>
        <collision>
            <origin xyz="0.0 0.0 0.12507728437566967" rpy="0 0 0"/>
            <geometry>
                <box size="0.5825203289501653 0.4567255278517912 0.25015456875133935" />
            </geometry>
        </collision>
    </link>
    <joint name="Joint1_2" type="revolute">
       <parent link="1"/>
       <child  link="2"/>
       <origin rpy="0 0 0" xyz="0.29126016447508263 0.0 0.12507728437566967" />
     <axis xyz="0 1 1"/>
       <limit effort="0.0" lower="-3.14159" upper="3.14159" velocity="0.0"/>
    </joint>
    <link name="2">
        <inertial>
            <origin xyz="0.010133804471117605 -0.0 0.0" rpy="0 0 0"/>
            <mass value="1" />
            <inertia ixx="100" ixy="0" ixz="0" iyy="100" iyz="0" izz="100" />
        </inertial>
        <visual>
            <origin xyz="0.010133804471117605 -0.0 0.0" rpy="0 0 0"/>
            <geometry>
                <box size="0.02026760894223521 -0.0012311493253071583 0.0034884349878209374" />
            </geometry>
            <material name="Green">
                <color rgba="0 1 1 1"/>
            </material>
        </visual>
        <collision>
            <origin xyz="0.010133804471117605 -0.0 0.0" rpy="0 0 0"/>
            <geometry>
                <box size="0.02026760894223521 -0.0012311493253071583 0.0034884349878209374" />
            </geometry>
        </collision>
    </link>
    <joint name="Joint1_3" type="revolute">
       <parent link="1"/>
       <child  link="3"/>
       <origin rpy="0 0 0" xyz="0.0 0.0 0.25015456875133935" />
     <axis xyz="1 1 0"/>
       <limit effort="0.0" lower="-3.14159" upper="3.14159" velocity="0.0"/>
    </joint>
    <link name="3">
        <inertial>
            <origin xyz="0.0 0.0 0.0686040217287045" rpy="0 0 0"/>
            <mass value="1" />
            <inertia ixx="100" ixy="0" ixz="0" iyy="100" iyz="0" izz="100" />
        </inertial>
        <visual>
            <origin xyz="0.0 0.0 0.0686040217287045" rpy="0 0 0"/>
            <geometry>
                <box size="0.11905288081376342 0.16957099156443833 0.137208043457409" />
            </geometry>
            <material name="Green">
                <color rgba="0 1 1 1"/>
            </material>
        </visual>
        <collision>
            <origin xyz="0.0 0.0 0.0686040217287045" rpy="0 0 0"/>
            <geometry>
                <box size="0.11905288081376342 0.16957099156443833 0.137208043457409" />
            </geometry>
        </collision>
    </link>
    <joint name="Joint1_4" type="revolute">
       <parent link="1"/>
       <child  link="4"/>
       <origin rpy="0 0 0" xyz="-0.29126016447508263 0.0 0.12507728437566967" />
     <axis xyz="0 1 1"/>
       <limit effort="0.0" lower="-3.14159" upper="3.14159" velocity="0.0"/>
    </joint>
    <link name="4">
        <inertial>
            <origin xyz="-0.1799499327280167 0.0 0.0" rpy="0 0 0"/>
            <mass value="1" />
            <inertia ixx="100" ixy="0" ixz="0" iyy="100" iyz="0" izz="100" />
        </inertial>
        <visual>
            <origin xyz="-0.1799499327280167 0.0 0.0" rpy="0 0 0"/>
            <geometry>
                <box size="0.3598998654560334 0.2211306730101258 0.31890266807699763" />
            </geometry>
            <material name="Blue">
                <color rgba="0 1 0 1"/>
            </material>
        </visual>
        <collision>
            <origin xyz="-0.1799499327280167 0.0 0.0" rpy="0 0 0"/>
            <geometry>
                <box size="0.3598998654560334 0.2211306730101258 0.31890266807699763" />
            </geometry>
        </collision>
    </link>
    <joint name="Joint1_5" type="revolute">
       <parent link="1"/>
       <child  link="5"/>
       <origin rpy="0 0 0" xyz="0.0 0.2283627639258956 0.12507728437566967" />
     <axis xyz="1 0 1"/>
       <limit effort="0.0" lower="-3.14159" upper="3.14159" velocity="0.0"/>
    </joint>
    <link name="5">
        <inertial>
            <origin xyz="0.0 0.28623182846062034 0.0" rpy="0 0 0"/>
            <mass value="1" />
            <inertia ixx="100" ixy="0" ixz="0" iyy="100" iyz="0" izz="100" />
        </inertial>
        <visual>
            <origin xyz="0.0 0.28623182846062034 0.0" rpy="0 0 0"/>
            <geometry>
                <box size="0.4855015830110791 0.5724636569212407 0.2743799507728063" />
            </geometry>
            <material name="Green">
                <color rgba="0 1 1 1"/>
            </material>
        </visual>
        <collision>
            <origin xyz="0.0 0.28623182846062034 0.0" rpy="0 0 0"/>
            <geometry>
                <box size="0.4855015830110791 0.5724636569212407 0.2743799507728063" />
            </geometry>
        </collision>
    </link>
    <joint name="Joint4_6" type="revolute">
       <parent link="4"/>
       <child  link="6"/>
       <origin rpy="0 0 0" xyz="-0.1799499327280167 -0.1105653365050629 0.0" />
     <axis xyz="1 0 1"/>
       <limit effort="0.0" lower="-3.14159" upper="3.14159" velocity="0.0"/>
    </joint>
    <link name="6">
        <inertial>
            <origin xyz="0.0 0.002211840658398317 0.0" rpy="0 0 0"/>
            <mass value="1" />
            <inertia ixx="100" ixy="0" ixz="0" iyy="100" iyz="0" izz="100" />
        </inertial>
        <visual>
            <origin xyz="0.0 0.002211840658398317 0.0" rpy="0 0 0"/>
            <geometry>
                <box size="0.0023961519531680935 -0.004423681316796634 -0.0024103884758027386" />
            </geometry>
            <material name="Green">
                <color rgba="0 1 1 1"/>
            </material>
        </visual>
        <collision>
            <origin xyz="0.0 0.002211840658398317 0.0" rpy="0 0 0"/>
            <geometry>
                <box size="0.0023961519531680935 -0.004423681316796634 -0.0024103884758027386" />
            </geometry>
        </collision>
    </link>
    <joint name="Joint5_7" type="revolute">
       <parent link="5"/>
       <child  link="7"/>
       <origin rpy="0 0 0" xyz="0.0 0.28623182846062034 0.13718997538640315" />
     <axis xyz="1 1 0"/>
       <limit effort="0.0" lower="-3.14159" upper="3.14159" velocity="0.0"/>
    </joint>
    <link name="7">
        <inertial>
            <origin xyz="0.0 0.0 0.19799173532907716" rpy="0 0 0"/>
            <mass value="1" />
            <inertia ixx="100" ixy="0" ixz="0" iyy="100" iyz="0" izz="100" />
        </inertial>
        <visual>
            <origin xyz="0.0 0.0 0.19799173532907716" rpy="0 0 0"/>
            <geometry>
                <box size="0.626169378862578 0.20600899707492618 0.3959834706581543" />
            </geometry>
            <material name="Green">
                <color rgba="0 1 1 1"/>
            </material>
        </visual>
        <collision>
            <origin xyz="0.0 0.0 0.19799173532907716" rpy="0 0 0"/>
            <geometry>
                <box size="0.626169378862578 0.20600899707492618 0.3959834706581543" />
            </geometry>
        </collision>
    </link>
    <joint name="Joint6_8" type="revolute">
       <parent link="6"/>
       <child  link="8"/>
       <origin rpy="0 0 0" xyz="0.0 0.002211840658398317 -0.0012051942379013693" />
     <axis xyz="1 1 0"/>
       <limit effort="0.0" lower="-3.14159" upper="3.14159" velocity="0.0"/>
    </joint>
    <link name="8">
        <inertial>
            <origin xyz="0.0 0.0 0.09374685775818176" rpy="0 0 0"/>
            <mass value="1" />
            <inertia ixx="100" ixy="0" ixz="0" iyy="100" iyz="0" izz="100" />
        </inertial>
        <visual>
            <origin xyz="0.0 0.0 0.09374685775818176" rpy="0 0 0"/>
            <geometry>
                <box size="0.16068589470244737 0.36331759477214565 0.1874937155163635" />
            </geometry>
            <material name="Green">
                <color rgba="0 1 1 1"/>
            </material>
        </visual>
        <collision>
            <origin xyz="0.0 0.0 0.09374685775818176" rpy="0 0 0"/>
            <geometry>
                <box size="0.16068589470244737 0.36331759477214565 0.1874937155163635" />
            </geometry>
        </collision>
    </link>
    <joint name="Joint8_9" type="revolute">
       <parent link="8"/>
       <child  link="9"/>
       <origin rpy="0 0 0" xyz="0.08034294735122369 0.0 0.09374685775818176" />
     <axis xyz="0 1 1"/>
       <limit effort="0.0" lower="-3.14159" upper="3.14159" velocity="0.0"/>
    </joint>
    <link name="9">
        <inertial>
            <origin xyz="0.17795470186256437 0.0 0.0" rpy="0 0 0"/>
            <mass value="1" />
            <inertia ixx="100" ixy="0" ixz="0" iyy="100" iyz="0" izz="100" />
        </inertial>
        <visual>
            <origin xyz="0.17795470186256437 0.0 0.0" rpy="0 0 0"/>
            <geometry>
                <box size="0.35590940372512875 0.13606286938103207 0.11157669126753031" />
            </geometry>
            <material name="Green">
                <color rgba="0 1 1 1"/>
            </material>
        </visual>
        <collision>
            <origin xyz="0.17795470186256437 0.0 0.0" rpy="0 0 0"/>
            <geometry>
                <box size="0.35590940372512875 0.13606286938103207 0.11157669126753031" />
            </geometry>
        </collision>
    </link>
</robot>