<robot name = "robot">
    <link name="0">
        <inertial>
            <origin xyz="0 0 0.9308606898529417" rpy="0 0 0"/>
            <mass value="1" />
            <inertia ixx="100" ixy="0" ixz="0" iyy="100" iyz="0" izz="100" />
        </inertial>
        <visual>
            <origin xyz="0 0 0.9308606898529417" rpy="0 0 0"/>
            <geometry>
                <box size="0.5657958857350782 0.6535322182941985 0.6206452505752571" />
            </geometry>
            <material name="Cyan">
                <color rgba="0 1 0 1"/>
            </material>
        </visual>
        <collision>
            <origin xyz="0 0 0.9308606898529417" rpy="0 0 0"/>
            <geometry>
                <box size="0.5657958857350782 0.6535322182941985 0.6206452505752571" />
            </geometry>
        </collision>
    </link>
    <joint name="Joint0_1" type="revolute">
       <parent link="0"/>
       <child  link="1"/>
       <origin rpy="0 0 0" xyz="-0.2828979428675391 0.0 0.0" />
     <axis xyz="0 1 0"/>
       <limit effort="0.0" lower="-3.14159" upper="3.14159" velocity="0.0"/>
    </joint>
    <link name="1">
        <inertial>
            <origin xyz="-0.31876516799304944 0.0 0.9308606898529417" rpy="0 0 0"/>
            <mass value="1" />
            <inertia ixx="100" ixy="0" ixz="0" iyy="100" iyz="0" izz="100" />
        </inertial>
        <visual>
            <origin xyz="-0.31876516799304944 0.0 0.9308606898529417" rpy="0 0 0"/>
            <geometry>
                <box size="0.6375303359860989 0.33864139906923246 0.23356833340170396" />
            </geometry>
            <material name="Blue">
                <color rgba="0 1 0 1"/>
            </material>
        </visual>
        <collision>
            <origin xyz="-0.31876516799304944 0.0 0.9308606898529417" rpy="0 0 0"/>
            <geometry>
                <box size="0.6375303359860989 0.33864139906923246 0.23356833340170396" />
            </geometry>
        </collision>
    </link>
    <joint name="Joint0_2" type="revolute">
       <parent link="0"/>
       <child  link="2"/>
       <origin rpy="0 0 0" xyz="0.0 0.0 -0.31032262528762855" />
     <axis xyz="0 1 0"/>
       <limit effort="0.0" lower="-3.14159" upper="3.14159" velocity="0.0"/>
    </joint>
    <link name="2">
        <inertial>
            <origin xyz="0.0 0.0 0.6205916575702851" rpy="0 0 0"/>
            <mass value="1" />
            <inertia ixx="100" ixy="0" ixz="0" iyy="100" iyz="0" izz="100" />
        </inertial>
        <visual>
            <origin xyz="0.0 0.0 0.6205916575702851" rpy="0 0 0"/>
            <geometry>
                <box size="0.0684105077725534 0.5640800287297367 0.6205380645653131" />
            </geometry>
            <material name="Blue">
                <color rgba="0 1 0 1"/>
            </material>
        </visual>
        <collision>
            <origin xyz="0.0 0.0 0.6205916575702851" rpy="0 0 0"/>
            <geometry>
                <box size="0.0684105077725534 0.5640800287297367 0.6205380645653131" />
            </geometry>
        </collision>
    </link>
    <joint name="Joint1_3" type="revolute">
       <parent link="1"/>
       <child  link="3"/>
       <origin rpy="0 0 0" xyz="-0.31876516799304944 0.16932069953461623 0.0" />
     <axis xyz="1 0 0"/>
       <limit effort="0.0" lower="-3.14159" upper="3.14159" velocity="0.0"/>
    </joint>
    <link name="3">
        <inertial>
            <origin xyz="0.0 0.16040983421967958 0.9308606898529417" rpy="0 0 0"/>
            <mass value="1" />
            <inertia ixx="100" ixy="0" ixz="0" iyy="100" iyz="0" izz="100" />
        </inertial>
        <visual>
            <origin xyz="0.0 0.16040983421967958 0.9308606898529417" rpy="0 0 0"/>
            <geometry>
                <box size="0.5577254788333117 0.32081966843935916 0.20329568125498632" />
            </geometry>
            <material name="Blue">
                <color rgba="0 1 0 1"/>
            </material>
        </visual>
        <collision>
            <origin xyz="0.0 0.16040983421967958 0.9308606898529417" rpy="0 0 0"/>
            <geometry>
                <box size="0.5577254788333117 0.32081966843935916 0.20329568125498632" />
            </geometry>
        </collision>
    </link>
    <joint name="Joint2_4" type="revolute">
       <parent link="2"/>
       <child  link="4"/>
       <origin rpy="0 0 0" xyz="0.0 -0.28204001436486836 -0.31026903228265656" />
     <axis xyz="1 0 0"/>
       <limit effort="0.0" lower="-3.14159" upper="3.14159" velocity="0.0"/>
    </joint>
    <link name="4">
        <inertial>
            <origin xyz="0.0 -0.03073091967556902 0.9308606898529417" rpy="0 0 0"/>
            <mass value="1" />
            <inertia ixx="100" ixy="0" ixz="0" iyy="100" iyz="0" izz="100" />
        </inertial>
        <visual>
            <origin xyz="0.0 -0.03073091967556902 0.9308606898529417" rpy="0 0 0"/>
            <geometry>
                <box size="0.6138987222496068 0.06146183935113804 0.2728681745748387" />
            </geometry>
            <material name="Blue">
                <color rgba="0 1 0 1"/>
            </material>
        </visual>
        <collision>
            <origin xyz="0.0 -0.03073091967556902 0.9308606898529417" rpy="0 0 0"/>
            <geometry>
                <box size="0.6138987222496068 0.06146183935113804 0.2728681745748387" />
            </geometry>
        </collision>
    </link>
</robot>