<robot name = "robot">
    <link name="Back0">
        <inertial>
            <origin xyz="0 0 0" rpy="0 0 0"/>
            <mass value="1" />
            <inertia ixx="100" ixy="0" ixz="0" iyy="100" iyz="0" izz="100" />
        </inertial>
        <visual>
            <origin xyz="0 0 0" rpy="0 0 0"/>
            <geometry>
                <box size="0.5859167134605248 0.13398518386646724 0.6302379595996388" />
            </geometry>
            <material name="Green">
                <color rgba="0 1 1 1"/>
            </material>
        </visual>
        <collision>
            <origin xyz="0 0 0" rpy="0 0 0"/>
            <geometry>
                <box size="0.5859167134605248 0.13398518386646724 0.6302379595996388" />
            </geometry>
        </collision>
    </link>
    <joint name="Back0_Back1" type="revolute">
       <parent link="Back0"/>
       <child  link="Back1"/>
       <origin rpy="0 0 0" xyz="0 -0.06699259193323362 0.0" />
     <axis xyz="0 0 1"/>
       <limit effort="0.0" lower="-3.14159" upper="3.14159" velocity="0.0"/>
    </joint>
    <link name="Back1">
        <inertial>
            <origin xyz="0 -0.17165596431313013 -0.15" rpy="0 0 0"/>
            <mass value="1" />
            <inertia ixx="100" ixy="0" ixz="0" iyy="100" iyz="0" izz="100" />
        </inertial>
        <visual>
            <origin xyz="0 -0.17165596431313013 -0.15" rpy="0 0 0"/>
            <geometry>
                <box size="0.08203967803553541 0.34331192862626025 0.4022155237464073" />
            </geometry>
            <material name="Green">
                <color rgba="0 1 1 1"/>
            </material>
        </visual>
        <collision>
            <origin xyz="0 -0.17165596431313013 -0.15" rpy="0 0 0"/>
            <geometry>
                <box size="0.08203967803553541 0.34331192862626025 0.4022155237464073" />
            </geometry>
        </collision>
    </link>
    <joint name="Back1_Back2" type="revolute">
       <parent link="Back1"/>
       <child  link="Back2"/>
       <origin rpy="0 0 0" xyz="0 -0.34331192862626025 0.0" />
     <axis xyz="0 0 1"/>
       <limit effort="0.0" lower="-3.14159" upper="3.14159" velocity="0.0"/>
    </joint>
    <link name="Back2">
        <inertial>
            <origin xyz="0 -0.17173563979487824 -0.15" rpy="0 0 0"/>
            <mass value="1" />
            <inertia ixx="100" ixy="0" ixz="0" iyy="100" iyz="0" izz="100" />
        </inertial>
        <visual>
            <origin xyz="0 -0.17173563979487824 -0.15" rpy="0 0 0"/>
            <geometry>
                <box size="0.2392717188268411 0.3434712795897565 0.51098605502738" />
            </geometry>
            <material name="Green">
                <color rgba="0 1 1 1"/>
            </material>
        </visual>
        <collision>
            <origin xyz="0 -0.17173563979487824 -0.15" rpy="0 0 0"/>
            <geometry>
                <box size="0.2392717188268411 0.3434712795897565 0.51098605502738" />
            </geometry>
        </collision>
    </link>
    <joint name="Back2_Back3" type="revolute">
       <parent link="Back2"/>
       <child  link="Back3"/>
       <origin rpy="0 0 0" xyz="0 -0.3434712795897565 0.0" />
     <axis xyz="1 0 0"/>
       <limit effort="0.0" lower="-3.14159" upper="3.14159" velocity="0.0"/>
    </joint>
    <link name="Back3">
        <inertial>
            <origin xyz="0 -0.12761159164919988 -0.15" rpy="0 0 0"/>
            <mass value="1" />
            <inertia ixx="100" ixy="0" ixz="0" iyy="100" iyz="0" izz="100" />
        </inertial>
        <visual>
            <origin xyz="0 -0.12761159164919988 -0.15" rpy="0 0 0"/>
            <geometry>
                <box size="0.25568286290897013 0.25522318329839977 0.23463952198423724" />
            </geometry>
            <material name="Blue">
                <color rgba="0 1 0 1"/>
            </material>
        </visual>
        <collision>
            <origin xyz="0 -0.12761159164919988 -0.15" rpy="0 0 0"/>
            <geometry>
                <box size="0.25568286290897013 0.25522318329839977 0.23463952198423724" />
            </geometry>
        </collision>
    </link>
    <joint name="Back3_Back4" type="revolute">
       <parent link="Back3"/>
       <child  link="Back4"/>
       <origin rpy="0 0 0" xyz="0 -0.25522318329839977 0.0" />
     <axis xyz="0 0 1"/>
       <limit effort="0.0" lower="-3.14159" upper="3.14159" velocity="0.0"/>
    </joint>
    <link name="Back4">
        <inertial>
            <origin xyz="0 -0.15153212620924186 -0.15" rpy="0 0 0"/>
            <mass value="1" />
            <inertia ixx="100" ixy="0" ixz="0" iyy="100" iyz="0" izz="100" />
        </inertial>
        <visual>
            <origin xyz="0 -0.15153212620924186 -0.15" rpy="0 0 0"/>
            <geometry>
                <box size="0.5459538366417771 0.3030642524184837 0.5501197764250361" />
            </geometry>
            <material name="Blue">
                <color rgba="0 1 0 1"/>
            </material>
        </visual>
        <collision>
            <origin xyz="0 -0.15153212620924186 -0.15" rpy="0 0 0"/>
            <geometry>
                <box size="0.5459538366417771 0.3030642524184837 0.5501197764250361" />
            </geometry>
        </collision>
    </link>
    <joint name="Back4_Back5" type="revolute">
       <parent link="Back4"/>
       <child  link="Back5"/>
       <origin rpy="0 0 0" xyz="0 -0.3030642524184837 0.0" />
     <axis xyz="0 0 1"/>
       <limit effort="0.0" lower="-3.14159" upper="3.14159" velocity="0.0"/>
    </joint>
    <link name="Back5">
        <inertial>
            <origin xyz="0 -0.10448349670570871 -0.15" rpy="0 0 0"/>
            <mass value="1" />
            <inertia ixx="100" ixy="0" ixz="0" iyy="100" iyz="0" izz="100" />
        </inertial>
        <visual>
            <origin xyz="0 -0.10448349670570871 -0.15" rpy="0 0 0"/>
            <geometry>
                <box size="0.40191102800540096 0.20896699341141742 0.2942599389429492" />
            </geometry>
            <material name="Blue">
                <color rgba="0 1 0 1"/>
            </material>
        </visual>
        <collision>
            <origin xyz="0 -0.10448349670570871 -0.15" rpy="0 0 0"/>
            <geometry>
                <box size="0.40191102800540096 0.20896699341141742 0.2942599389429492" />
            </geometry>
        </collision>
    </link>
    <joint name="Back5_Back6" type="revolute">
       <parent link="Back5"/>
       <child  link="Back6"/>
       <origin rpy="0 0 0" xyz="0 -0.20896699341141742 0.0" />
     <axis xyz="1 0 0"/>
       <limit effort="0.0" lower="-3.14159" upper="3.14159" velocity="0.0"/>
    </joint>
    <link name="Back6">
        <inertial>
            <origin xyz="0 -0.18416162153073296 -0.15" rpy="0 0 0"/>
            <mass value="1" />
            <inertia ixx="100" ixy="0" ixz="0" iyy="100" iyz="0" izz="100" />
        </inertial>
        <visual>
            <origin xyz="0 -0.18416162153073296 -0.15" rpy="0 0 0"/>
            <geometry>
                <box size="0.5552562244839012 0.3683232430614659 0.6166375536563524" />
            </geometry>
            <material name="Blue">
                <color rgba="0 1 0 1"/>
            </material>
        </visual>
        <collision>
            <origin xyz="0 -0.18416162153073296 -0.15" rpy="0 0 0"/>
            <geometry>
                <box size="0.5552562244839012 0.3683232430614659 0.6166375536563524" />
            </geometry>
        </collision>
    </link>
    <joint name="Back6_Back7" type="revolute">
       <parent link="Back6"/>
       <child  link="Back7"/>
       <origin rpy="0 0 0" xyz="0 -0.3683232430614659 0.0" />
     <axis xyz="0 0 1"/>
       <limit effort="0.0" lower="-3.14159" upper="3.14159" velocity="0.0"/>
    </joint>
    <link name="Back7">
        <inertial>
            <origin xyz="0 -0.04964212778395223 -0.15" rpy="0 0 0"/>
            <mass value="1" />
            <inertia ixx="100" ixy="0" ixz="0" iyy="100" iyz="0" izz="100" />
        </inertial>
        <visual>
            <origin xyz="0 -0.04964212778395223 -0.15" rpy="0 0 0"/>
            <geometry>
                <box size="0.2572243761119811 0.09928425556790446 0.47933400375609614" />
            </geometry>
            <material name="Green">
                <color rgba="0 1 1 1"/>
            </material>
        </visual>
        <collision>
            <origin xyz="0 -0.04964212778395223 -0.15" rpy="0 0 0"/>
            <geometry>
                <box size="0.2572243761119811 0.09928425556790446 0.47933400375609614" />
            </geometry>
        </collision>
    </link>
    <joint name="Back7_Back8" type="revolute">
       <parent link="Back7"/>
       <child  link="Back8"/>
       <origin rpy="0 0 0" xyz="0 -0.09928425556790446 0.0" />
     <axis xyz="0 0 1"/>
       <limit effort="0.0" lower="-3.14159" upper="3.14159" velocity="0.0"/>
    </joint>
    <link name="Back8">
        <inertial>
            <origin xyz="0 -0.05499598012665957 -0.15" rpy="0 0 0"/>
            <mass value="1" />
            <inertia ixx="100" ixy="0" ixz="0" iyy="100" iyz="0" izz="100" />
        </inertial>
        <visual>
            <origin xyz="0 -0.05499598012665957 -0.15" rpy="0 0 0"/>
            <geometry>
                <box size="0.5151881089222463 0.10999196025331914 0.1365381081819554" />
            </geometry>
            <material name="Blue">
                <color rgba="0 1 0 1"/>
            </material>
        </visual>
        <collision>
            <origin xyz="0 -0.05499598012665957 -0.15" rpy="0 0 0"/>
            <geometry>
                <box size="0.5151881089222463 0.10999196025331914 0.1365381081819554" />
            </geometry>
        </collision>
    </link>
    <joint name="Back8_Back9" type="revolute">
       <parent link="Back8"/>
       <child  link="Back9"/>
       <origin rpy="0 0 0" xyz="0 -0.10999196025331914 0.0" />
     <axis xyz="1 0 0"/>
       <limit effort="0.0" lower="-3.14159" upper="3.14159" velocity="0.0"/>
    </joint>
    <link name="Back9">
        <inertial>
            <origin xyz="0 -0.26759494462006617 -0.15" rpy="0 0 0"/>
            <mass value="1" />
            <inertia ixx="100" ixy="0" ixz="0" iyy="100" iyz="0" izz="100" />
        </inertial>
        <visual>
            <origin xyz="0 -0.26759494462006617 -0.15" rpy="0 0 0"/>
            <geometry>
                <box size="0.2931416957532884 0.5351898892401323 0.5702453791261204" />
            </geometry>
            <material name="Blue">
                <color rgba="0 1 0 1"/>
            </material>
        </visual>
        <collision>
            <origin xyz="0 -0.26759494462006617 -0.15" rpy="0 0 0"/>
            <geometry>
                <box size="0.2931416957532884 0.5351898892401323 0.5702453791261204" />
            </geometry>
        </collision>
    </link>
</robot>