<robot name = "robot">
    <link name="0">
        <inertial>
            <origin xyz="0 0 0" rpy="0 0 0"/>
            <mass value="1" />
            <inertia ixx="100" ixy="0" ixz="0" iyy="100" iyz="0" izz="100" />
        </inertial>
        <visual>
            <origin xyz="0 0 0" rpy="0 0 0"/>
            <geometry>
                <box size="0.2944906588147529 0.65401446132317 0.4905035342491253" />
            </geometry>
            <material name="Cyan">
                <color rgba="0 1 1 1"/>
            </material>
        </visual>
        <collision>
            <origin xyz="0 0 0" rpy="0 0 0"/>
            <geometry>
                <box size="0.2944906588147529 0.65401446132317 0.4905035342491253" />
            </geometry>
        </collision>
    </link>
    <joint name="Joint0_1" type="revolute">
       <parent link="0"/>
       <child  link="1"/>
       <origin rpy="0 0 0" xyz="0.0 0.0 0.24525176712456265" />
     <axis xyz="1 1 0"/>
       <limit effort="0.0" lower="-3.14159" upper="3.14159" velocity="0.0"/>
    </joint>
    <link name="1">
        <inertial>
            <origin xyz="0.0 0.0 0.16916370281820178" rpy="0 0 0"/>
            <mass value="1" />
            <inertia ixx="100" ixy="0" ixz="0" iyy="100" iyz="0" izz="100" />
        </inertial>
        <visual>
            <origin xyz="0.0 0.0 0.16916370281820178" rpy="0 0 0"/>
            <geometry>
                <box size="0.6323071438211296 0.2964336041392858 0.33832740563640357" />
            </geometry>
            <material name="Green">
                <color rgba="0 1 1 1"/>
            </material>
        </visual>
        <collision>
            <origin xyz="0.0 0.0 0.16916370281820178" rpy="0 0 0"/>
            <geometry>
                <box size="0.6323071438211296 0.2964336041392858 0.33832740563640357" />
            </geometry>
        </collision>
    </link>
    <joint name="Joint1_2" type="revolute">
       <parent link="1"/>
       <child  link="2"/>
       <origin rpy="0 0 0" xyz="0.0 0.0 0.33832740563640357" />
     <axis xyz="1 1 0"/>
       <limit effort="0.0" lower="-3.14159" upper="3.14159" velocity="0.0"/>
    </joint>
    <link name="2">
        <inertial>
            <origin xyz="0.0 0.0 0.04981358322117525" rpy="0 0 0"/>
            <mass value="1" />
            <inertia ixx="100" ixy="0" ixz="0" iyy="100" iyz="0" izz="100" />
        </inertial>
        <visual>
            <origin xyz="0.0 0.0 0.04981358322117525" rpy="0 0 0"/>
            <geometry>
                <box size="0.24517913541264555 0.38634891064704424 0.0996271664423505" />
            </geometry>
            <material name="Green">
                <color rgba="0 1 1 1"/>
            </material>
        </visual>
        <collision>
            <origin xyz="0.0 0.0 0.04981358322117525" rpy="0 0 0"/>
            <geometry>
                <box size="0.24517913541264555 0.38634891064704424 0.0996271664423505" />
            </geometry>
        </collision>
    </link>
    <joint name="Joint1_4" type="revolute">
       <parent link="1"/>
       <child  link="4"/>
       <origin rpy="0 0 0" xyz="0.0 -0.1482168020696429 0.16916370281820178" />
     <axis xyz="1 0 1"/>
       <limit effort="0.0" lower="-3.14159" upper="3.14159" velocity="0.0"/>
    </joint>
    <link name="4">
        <inertial>
            <origin xyz="0.0 -0.29554776288074736 0.0" rpy="0 0 0"/>
            <mass value="1" />
            <inertia ixx="100" ixy="0" ixz="0" iyy="100" iyz="0" izz="100" />
        </inertial>
        <visual>
            <origin xyz="0.0 -0.29554776288074736 0.0" rpy="0 0 0"/>
            <geometry>
                <box size="0.5169826668876746 0.5910955257614947 0.13134354429915063" />
            </geometry>
            <material name="Blue">
                <color rgba="0 1 0 1"/>
            </material>
        </visual>
        <collision>
            <origin xyz="0.0 -0.29554776288074736 0.0" rpy="0 0 0"/>
            <geometry>
                <box size="0.5169826668876746 0.5910955257614947 0.13134354429915063" />
            </geometry>
        </collision>
    </link>
    <joint name="Joint2_3" type="revolute">
       <parent link="2"/>
       <child  link="3"/>
       <origin rpy="0 0 0" xyz="0.0 0.19317445532352212 0.04981358322117525" />
     <axis xyz="1 0 1"/>
       <limit effort="0.0" lower="-3.14159" upper="3.14159" velocity="0.0"/>
    </joint>
    <link name="3">
        <inertial>
            <origin xyz="0.0 0.03458685503294285 0.0" rpy="0 0 0"/>
            <mass value="1" />
            <inertia ixx="100" ixy="0" ixz="0" iyy="100" iyz="0" izz="100" />
        </inertial>
        <visual>
            <origin xyz="0.0 0.03458685503294285 0.0" rpy="0 0 0"/>
            <geometry>
                <box size="0.3556421647323084 0.0691737100658857 0.31160605885243464" />
            </geometry>
            <material name="Green">
                <color rgba="0 1 1 1"/>
            </material>
        </visual>
        <collision>
            <origin xyz="0.0 0.03458685503294285 0.0" rpy="0 0 0"/>
            <geometry>
                <box size="0.3556421647323084 0.0691737100658857 0.31160605885243464" />
            </geometry>
        </collision>
    </link>
    <joint name="Joint4_5" type="revolute">
       <parent link="4"/>
       <child  link="5"/>
       <origin rpy="0 0 0" xyz="0.0 -0.5910955257614947 0.0" />
     <axis xyz="1 0 1"/>
       <limit effort="0.0" lower="-3.14159" upper="3.14159" velocity="0.0"/>
    </joint>
    <link name="5">
        <inertial>
            <origin xyz="0.0 -0.18461759169154413 0.0" rpy="0 0 0"/>
            <mass value="1" />
            <inertia ixx="100" ixy="0" ixz="0" iyy="100" iyz="0" izz="100" />
        </inertial>
        <visual>
            <origin xyz="0.0 -0.18461759169154413 0.0" rpy="0 0 0"/>
            <geometry>
                <box size="0.09576335611378453 0.36923518338308825 0.06837225241105255" />
            </geometry>
            <material name="Green">
                <color rgba="0 1 1 1"/>
            </material>
        </visual>
        <collision>
            <origin xyz="0.0 -0.18461759169154413 0.0" rpy="0 0 0"/>
            <geometry>
                <box size="0.09576335611378453 0.36923518338308825 0.06837225241105255" />
            </geometry>
        </collision>
    </link>
    <joint name="Joint4_6" type="revolute">
       <parent link="4"/>
       <child  link="6"/>
       <origin rpy="0 0 0" xyz="-0.2584913334438373 -0.29554776288074736 0.0" />
     <axis xyz="0 1 1"/>
       <limit effort="0.0" lower="-3.14159" upper="3.14159" velocity="0.0"/>
    </joint>
    <link name="6">
        <inertial>
            <origin xyz="-0.0024326773833411993 0.0 0.0" rpy="0 0 0"/>
            <mass value="1" />
            <inertia ixx="100" ixy="0" ixz="0" iyy="100" iyz="0" izz="100" />
        </inertial>
        <visual>
            <origin xyz="-0.0024326773833411993 0.0 0.0" rpy="0 0 0"/>
            <geometry>
                <box size="0.004865354766682399 0.004633689493618945 -0.001989365503935288" />
            </geometry>
            <material name="Green">
                <color rgba="0 1 1 1"/>
            </material>
        </visual>
        <collision>
            <origin xyz="-0.0024326773833411993 0.0 0.0" rpy="0 0 0"/>
            <geometry>
                <box size="0.004865354766682399 0.004633689493618945 -0.001989365503935288" />
            </geometry>
        </collision>
    </link>
    <joint name="Joint4_8" type="revolute">
       <parent link="4"/>
       <child  link="8"/>
       <origin rpy="0 0 0" xyz="0.0 -0.29554776288074736 0.06567177214957531" />
     <axis xyz="1 1 0"/>
       <limit effort="0.0" lower="-3.14159" upper="3.14159" velocity="0.0"/>
    </joint>
    <link name="8">
        <inertial>
            <origin xyz="0.0 0.0 0.03013696942466943" rpy="0 0 0"/>
            <mass value="1" />
            <inertia ixx="100" ixy="0" ixz="0" iyy="100" iyz="0" izz="100" />
        </inertial>
        <visual>
            <origin xyz="0.0 0.0 0.03013696942466943" rpy="0 0 0"/>
            <geometry>
                <box size="0.3966587594052601 0.5257113556694502 0.06027393884933886" />
            </geometry>
            <material name="Green">
                <color rgba="0 1 1 1"/>
            </material>
        </visual>
        <collision>
            <origin xyz="0.0 0.0 0.03013696942466943" rpy="0 0 0"/>
            <geometry>
                <box size="0.3966587594052601 0.5257113556694502 0.06027393884933886" />
            </geometry>
        </collision>
    </link>
    <joint name="Joint4_9" type="revolute">
       <parent link="4"/>
       <child  link="9"/>
       <origin rpy="0 0 0" xyz="0.2584913334438373 -0.29554776288074736 0.0" />
     <axis xyz="0 1 1"/>
       <limit effort="0.0" lower="-3.14159" upper="3.14159" velocity="0.0"/>
    </joint>
    <link name="9">
        <inertial>
            <origin xyz="0.2916683290296386 0.0 0.0" rpy="0 0 0"/>
            <mass value="1" />
            <inertia ixx="100" ixy="0" ixz="0" iyy="100" iyz="0" izz="100" />
        </inertial>
        <visual>
            <origin xyz="0.2916683290296386 0.0 0.0" rpy="0 0 0"/>
            <geometry>
                <box size="0.5833366580592771 0.5292232308542946 0.253960896291326" />
            </geometry>
            <material name="Green">
                <color rgba="0 1 1 1"/>
            </material>
        </visual>
        <collision>
            <origin xyz="0.2916683290296386 0.0 0.0" rpy="0 0 0"/>
            <geometry>
                <box size="0.5833366580592771 0.5292232308542946 0.253960896291326" />
            </geometry>
        </collision>
    </link>
    <joint name="Joint6_7" type="revolute">
       <parent link="6"/>
       <child  link="7"/>
       <origin rpy="0 0 0" xyz="-0.004865354766682399 0.0 -0.0" />
     <axis xyz="0 1 1"/>
       <limit effort="0.0" lower="-3.14159" upper="3.14159" velocity="0.0"/>
    </joint>
    <link name="7">
        <inertial>
            <origin xyz="-0.09023782390967333 0.0 0.0" rpy="0 0 0"/>
            <mass value="1" />
            <inertia ixx="100" ixy="0" ixz="0" iyy="100" iyz="0" izz="100" />
        </inertial>
        <visual>
            <origin xyz="-0.09023782390967333 0.0 0.0" rpy="0 0 0"/>
            <geometry>
                <box size="0.18047564781934666 0.33943797034719236 0.2482411210997125" />
            </geometry>
            <material name="Green">
                <color rgba="0 1 1 1"/>
            </material>
        </visual>
        <collision>
            <origin xyz="-0.09023782390967333 0.0 0.0" rpy="0 0 0"/>
            <geometry>
                <box size="0.18047564781934666 0.33943797034719236 0.2482411210997125" />
            </geometry>
        </collision>
    </link>
</robot>