<robot name = "robot">
    <link name="0">
        <inertial>
            <origin xyz="0 0 0" rpy="0 0 0"/>
            <mass value="1" />
            <inertia ixx="100" ixy="0" ixz="0" iyy="100" iyz="0" izz="100" />
        </inertial>
        <visual>
            <origin xyz="0 0 0" rpy="0 0 0"/>
            <geometry>
                <box size="0.42722299421079324 0.20125702391245628 0.10781331187183484" />
            </geometry>
            <material name="Cyan">
                <color rgba="0 1 0 1"/>
            </material>
        </visual>
        <collision>
            <origin xyz="0 0 0" rpy="0 0 0"/>
            <geometry>
                <box size="0.42722299421079324 0.20125702391245628 0.10781331187183484" />
            </geometry>
        </collision>
    </link>
    <joint name="Joint0_1" type="revolute">
       <parent link="0"/>
       <child  link="1"/>
       <origin rpy="0 0 0" xyz="0.0 0.0 0.05390665593591742" />
     <axis xyz="1 1 0"/>
       <limit effort="0.0" lower="-3.14159" upper="3.14159" velocity="0.0"/>
    </joint>
    <link name="1">
        <inertial>
            <origin xyz="0.0 0.0 0.11716034374623827" rpy="0 0 0"/>
            <mass value="1" />
            <inertia ixx="100" ixy="0" ixz="0" iyy="100" iyz="0" izz="100" />
        </inertial>
        <visual>
            <origin xyz="0.0 0.0 0.11716034374623827" rpy="0 0 0"/>
            <geometry>
                <box size="0.5234630309765937 0.19905182156781218 0.23432068749247653" />
            </geometry>
            <material name="Blue">
                <color rgba="0 1 0 1"/>
            </material>
        </visual>
        <collision>
            <origin xyz="0.0 0.0 0.11716034374623827" rpy="0 0 0"/>
            <geometry>
                <box size="0.5234630309765937 0.19905182156781218 0.23432068749247653" />
            </geometry>
        </collision>
    </link>
    <joint name="Joint1_2" type="revolute">
       <parent link="1"/>
       <child  link="2"/>
       <origin rpy="0 0 0" xyz="0.0 0.0 0.23432068749247653" />
     <axis xyz="1 1 0"/>
       <limit effort="0.0" lower="-3.14159" upper="3.14159" velocity="0.0"/>
    </joint>
    <link name="2">
        <inertial>
            <origin xyz="0.0 -0.0 0.12343309381620149" rpy="0 0 0"/>
            <mass value="1" />
            <inertia ixx="100" ixy="0" ixz="0" iyy="100" iyz="0" izz="100" />
        </inertial>
        <visual>
            <origin xyz="0.0 -0.0 0.12343309381620149" rpy="0 0 0"/>
            <geometry>
                <box size="0.1445157898770485 -3.52966524237363e-05 0.24686618763240298" />
            </geometry>
            <material name="Green">
                <color rgba="0 1 1 1"/>
            </material>
        </visual>
        <collision>
            <origin xyz="0.0 -0.0 0.12343309381620149" rpy="0 0 0"/>
            <geometry>
                <box size="0.1445157898770485 -3.52966524237363e-05 0.24686618763240298" />
            </geometry>
        </collision>
    </link>
    <joint name="Joint2_3" type="revolute">
       <parent link="2"/>
       <child  link="3"/>
       <origin rpy="0 0 0" xyz="0.0 -0.0 0.24686618763240298" />
     <axis xyz="1 1 0"/>
       <limit effort="0.0" lower="-3.14159" upper="3.14159" velocity="0.0"/>
    </joint>
    <link name="3">
        <inertial>
            <origin xyz="0.0 0.0 0.3010663449690725" rpy="0 0 0"/>
            <mass value="1" />
            <inertia ixx="100" ixy="0" ixz="0" iyy="100" iyz="0" izz="100" />
        </inertial>
        <visual>
            <origin xyz="0.0 0.0 0.3010663449690725" rpy="0 0 0"/>
            <geometry>
                <box size="0.6006538094115919 0.38367433726907096 0.602132689938145" />
            </geometry>
            <material name="Blue">
                <color rgba="0 1 0 1"/>
            </material>
        </visual>
        <collision>
            <origin xyz="0.0 0.0 0.3010663449690725" rpy="0 0 0"/>
            <geometry>
                <box size="0.6006538094115919 0.38367433726907096 0.602132689938145" />
            </geometry>
        </collision>
    </link>
    <joint name="Joint3_4" type="revolute">
       <parent link="3"/>
       <child  link="4"/>
       <origin rpy="0 0 0" xyz="-0.3003269047057959 0.0 0.3010663449690725" />
     <axis xyz="0 1 1"/>
       <limit effort="0.0" lower="-3.14159" upper="3.14159" velocity="0.0"/>
    </joint>
    <link name="4">
        <inertial>
            <origin xyz="-0.2888148501622608 0.0 0.0" rpy="0 0 0"/>
            <mass value="1" />
            <inertia ixx="100" ixy="0" ixz="0" iyy="100" iyz="0" izz="100" />
        </inertial>
        <visual>
            <origin xyz="-0.2888148501622608 0.0 0.0" rpy="0 0 0"/>
            <geometry>
                <box size="0.5776297003245217 0.3236145453788426 0.0016097371454035867" />
            </geometry>
            <material name="Blue">
                <color rgba="0 1 0 1"/>
            </material>
        </visual>
        <collision>
            <origin xyz="-0.2888148501622608 0.0 0.0" rpy="0 0 0"/>
            <geometry>
                <box size="0.5776297003245217 0.3236145453788426 0.0016097371454035867" />
            </geometry>
        </collision>
    </link>
</robot>